Workbook

Sheet timeseries
A1: t
A2: 44671
A3: 44671.042
A4: 44671.083
A5: 44671.125
A6: 44671.167
A7: 44671.208
A8: 44671.25
A9: 44671.292
A10: 44671.333
A11: 44671.375
A12: 44671.417
A13: 44671.458
... A481: 44690.958

Sheet setup
A1: parameter | B1: value
A2: use_market_bids | B2: 1
A3: use_reserves | B3: 1
A4: use_reserve_realisation | B4: 1
A5: use_node_dummy_variables | B5: 1
A6: use_ramp_dummy_variables | B6: 1
A7: node_dummy_variable_cost | B7: 10000
A8: ramp_dummy_variable_cost | B8: 10000
A9: common_start_timesteps | B9: 2
A10: common_end_timesteps | B10: 2
A11: common_scenario_name | B11: s_all

Sheet nodes
A1: node | B1: is_commodity | C1: is_state | D1: is_res | E1: is_market | F1: is_inflow | G1: state_max | H1: state_min | I1: in_max | J1: out_max | K1: initial_state | L1: state_loss_proportional | M1: scenario_independent_state | N1: is_temp | O1: t_e_conversion | P1: residual_value
A2: ng | B2: 1 | C2: 0 | D2: 0 | E2: 0 | F2: 0 | G2: 0 | H2: 0 | I2: 0 | J2: 0 | K2: 0 | L2: 0 | M2: 0 | N2: 0 | O2: 1 | P2: 0
A3: elc | B3: 0 | C3: 0 | D3: 1 | E3: 0 | F3: 0 | G3: 0 | H3: 0 | I3: 0 | J3: 0 | K3: 0 | L3: 0 | M3: 0 | N3: 0 | O3: 1 | P3: 0
A4: dh | B4: 0 | C4: 0 | D4: 0 | E4: 0 | F4: 0 | G4: 0 | H4: 0 | I4: 0 | J4: 0 | K4: 0 | L4: 0 | M4: 0 | N4: 0 | O4: 1 | P4: 0
A5: h2 | B5: 0 | C5: 1 | D5: 0 | E5: 0 | F5: 1 | G5: 4 | H5: 0 | I5: 1 | J5: 1 | K5: 0 | L5: 0 | M5: 0 | N5: 0 | O5: 1 | P5: 0
A6: dh2 | B6: 0 | C6: 0 | D6: 0 | E6: 0 | F6: 1 | G6: 0 | H6: 0 | I6: 0 | J6: 0 | K6: 0 | L6: 0 | M6: 0 | N6: 0 | O6: 1 | P6: 0
A7: dh_sto | B7: 0 | C7: 1 | D7: 0 | E7: 0 | F7: 0 | G7: 393.15 | H7: 330.15 | I7: 20 | J7: 20 | K7: 373.15 | L7: 0 | M7: 0 | N7: 1 | O7: =1.16388888888889/5 -> 0.23277778 | P7: 20
A8: ambience | B8: 0 | C8: 1 | D8: 0 | E8: 0 | F8: 1 | G8: 300.15 | H8: 253.15 | I8: 100000000 | J8: 100000000 | K8: 273.15 | L8: 0 | M8: 0 | N8: 1 | O8: 10000000 | P8: 0
A9: delay_source | B9: 0 | C9: 0 | D9: 0 | E9: 0 | F9: 1 | G9: 0 | H9: 0 | I9: 0 | J9: 0 | K9: 0 | L9: 0 | M9: 0 | N9: 0 | O9: 1 | P9: 0
A10: dh_source | B10: 0 | C10: 1 | D10: 0 | E10: 0 | F10: 0 | G10: 1000 | H10: 0 | I10: 1000 | J10: 1000 | K10: 0 | L10: 0.9 | M10: 0 | N10: 0 | O10: 1 | P10: 0

Sheet processes
A1: process | B1: is_cf | C1: is_cf_fix | D1: is_online | E1: is_res | F1: conversion | G1: eff | H1: load_min | I1: load_max | J1: start_cost | K1: min_online | L1: min_offline | M1: max_online | N1: max_offline | O1: initial_state | P1: scenario_independent_online | Q1: delay
A2: ngchp | B2: 0 | C2: 0 | D2: 1 | E2: 1 | F2: 1 | G2: 0.9 | H2: 0.3 | I2: 1 | J2: 0 | K2: 4 | L2: 3 | M2: 0 | N2: 0 | O2: 1 | P2: 1 | Q2: 0
A3: hp1 | B3: 0 | C3: 0 | D3: 0 | E3: 1 | F3: 1 | G3: 3 | H3: 0 | I3: 1 | J3: 0 | K3: 0 | L3: 0 | M3: 0 | N3: 0 | O3: 0 | P3: 0 | Q3: 0
A4: p2x1 | B4: 0 | C4: 0 | D4: 0 | E4: 1 | F4: 1 | G4: 0.7 | H4: 0 | I4: 1 | J4: 0 | K4: 0 | L4: 0 | M4: 0 | N4: 0 | O4: 0 | P4: 0 | Q4: 0
A5: pv1 | B5: 1 | C5: 1 | D5: 0 | E5: 0 | F5: 1 | G5: 1 | H5: 0 | I5: 1 | J5: 0 | K5: 0 | L5: 0 | M5: 0 | N5: 0 | O5: 0 | P5: 0 | Q5: 0
A6: dh_tra | B6: 0 | C6: 0 | D6: 0 | E6: 0 | F6: 2 | G6: 0.99 | H6: 0 | I6: 1 | J6: 0 | K6: 0 | L6: 0 | M6: 0 | N6: 0 | O6: 0 | P6: 0 | Q6: 0
A7: dh_sto_charge | B7: 0 | C7: 0 | D7: 0 | E7: 0 | F7: 1 | G7: 0.99 | H7: 0 | I7: 1 | J7: 0 | K7: 0 | L7: 0 | M7: 0 | N7: 0 | O7: 0 | P7: 0 | Q7: 0
A8: dh_sto_discharge | B8: 0 | C8: 0 | D8: 0 | E8: 0 | F8: 1 | G8: 0.99 | H8: 0 | I8: 1 | J8: 0 | K8: 0 | L8: 0 | M8: 0 | N8: 0 | O8: 0 | P8: 0 | Q8: 0
A9: dh_source_out | B9: 0 | C9: 0 | D9: 0 | E9: 0 | F9: 2 | G9: 1 | H9: 0 | I9: 1 | J9: 0 | K9: 0 | L9: 0 | M9: 0 | N9: 0 | O9: 0 | P9: 0 | Q9: 0

Sheet groups
A1: group_type | B1: entity | C1: group
A2: process | B2: ngchp | C2: p1
A3: process | B3: hp1 | C3: p1
A4: process | B4: p2x1 | C4: p1
A5: node | B5: elc | C5: elc_res

Sheet efficiencies
A1: process | B1: 1 | C1: =B1+1 -> 2 | D1: =C1+1 -> 3 | E1: =D1+1 -> 4 | F1: =E1+1 -> 5 | G1: =F1+1 -> 6 | H1: =G1+1 -> 7 | I1: =H1+1 -> 8 | J1: =I1+1 -> 9 | K1: =J1+1 -> 10
A2: ngchp,op | B2: 0.4 | C2: 0.6 | D2: 0.8 | E2: 0.9 | F2: 1
A3: ngchp,eff | B3: 0.8 | C3: 0.78 | D3: 0.75 | E3: 0.7 | F3: 0.65

Sheet process_topology
A1: process | B1: source_sink | C1: node | D1: conversion_coeff | E1: capacity | F1: vom_cost | G1: ramp_up | H1: ramp_down | I1: initial_load | J1: initial_flow
A2: ngchp | B2: source | C2: ng | D2: 1 | E2: 20 | F2: 3 | G2: 0.5 | H2: 0.5 | I2: 0.6 | J2: 0.6
A3: ngchp | B3: sink | C3: dh | D3: 1 | E3: 10 | F3: 0 | G3: 0.5 | H3: 0.5 | I3: 0.6 | J3: 0.6
A4: ngchp | B4: sink | C4: elc | D4: 1 | E4: 8 | F4: 0 | G4: 0.5 | H4: 0.5 | I4: 0.6 | J4: 0.6
A5: hp1 | B5: source | C5: elc | D5: 1 | E5: 5 | F5: 15 | G5: 0.5 | H5: 0.5 | I5: 0.6 | J5: 0.6
A6: hp1 | B6: sink | C6: dh | D6: 1 | E6: 15 | F6: 0.5 | G6: 0.5 | H6: 0.5 | I6: 0.6 | J6: 0.6
A7: p2x1 | B7: source | C7: elc | D7: 1 | E7: 10 | F7: 15 | G7: 1 | H7: 1 | I7: 0.6 | J7: 0.6
A8: p2x1 | B8: sink | C8: h2 | D8: 1 | E8: 7 | F8: 1 | G8: 1 | H8: 1 | I8: 0.6 | J8: 0.6
A9: pv1 | B9: sink | C9: elc | D9: 1 | E9: 5 | F9: 0.5 | G9: 1 | H9: 1 | I9: 0.6 | J9: 0.6
A10: dh_tra | B10: source | C10: dh | D10: 1 | E10: 20 | F10: 0 | G10: 1 | H10: 1 | I10: 0.6 | J10: 0.6
A11: dh_tra | B11: sink | C11: dh2 | D11: 1 | E11: 20 | F11: 0 | G11: 1 | H11: 1 | I11: 0.6 | J11: 0.6
A12: dh_sto_charge | B12: source | C12: dh | D12: 1 | E12: 20 | F12: 0 | G12: 1 | H12: 1 | I12: 0.6 | J12: 0.6
A13: dh_sto_charge | B13: sink | C13: dh_sto | D13: 1 | E13: 20 | F13: 0 | G13: 1 | H13: 1 | I13: 0.6 | J13: 0.6
... A17: dh_source_out | B17: sink | C17: dh | D17: 1 | E17: 1000 | F17: 0 | G17: 1 | H17: 1 | I17: 0.6 | J17: 0.6

Sheet node_history
A1: t | B1: dh_source,t,s1 | C1: dh_source,s1 | D1: dh_source,t,s2 | E1: dh_source,s2 | F1: dh_source,t,s3 | G1: dh_source,s3 | H1: dh_source,t,s4 | I1: dh_source,s4 | J1: dh_source,t,s5 | K1: dh_source,s5 | L1: dh_source,t,s6 | M1: dh_source,s6 | N1: dh_source,t,s7 | O1: dh_source,s7 | P1: dh_source,t,s8 | Q1: dh_source,s8 | R1: dh_source,t,s9 | S1: dh_source,s9 | T1: dh_source,t,s10 | U1: dh_source,s10 | V1: dh_source,t,s11 | W1: dh_source,s11 | X1: dh_source,t,s12 | Y1: dh_source,s12 | Z1: dh_source,t,s13 | AA1: dh_source,s13 | AB1: dh_source,t,s14 | AC1: dh_source,s14 | AD1: dh_source,t,s15 | AE1: dh_source,s15 | AF1: dh_source,t,s16 | AG1: dh_source,s16 | AH1: dh_source,t,s17 | AI1: dh_source,s17 | AJ1: dh_source,t,s18 | AK1: dh_source,s18 | AL1: dh_source,t,s19 | AM1: dh_source,s19 | AN1: dh_source,t,s20 | AO1: dh_source,s20 | AP1: dh_source,t,s21 | AQ1: dh_source,s21 | AR1: dh_source,t,s22 | AS1: dh_source,s22 | AT1: dh_source,t,s23 | AU1: dh_source,s23 | AV1: dh_source,t,s24 | AW1: dh_source,s24 | AX1: dh_source,t,s25 | AY1: dh_source,s25 | AZ1: dh_source,t,s26 | BA1: dh_source,s26 | BB1: dh_source,t,s27 | BC1: dh_source,s27 | BD1: dh_source,t,s28 | BE1: dh_source,s28 | BF1: dh_source,t,s29 | BG1: dh_source,s29 | BH1: dh_source,t,s30 | BI1: dh_source,s30
A2: 1 | B2: 44671 | C2: 1 | D2: =B2 -> 44671 | E2: =C2 -> 1 | F2: =D2 -> 44671 | G2: =E2 -> 1 | H2: =F2 -> 44671 | I2: =G2 -> 1 | J2: =H2 -> 44671 | K2: =I2 -> 1 | ... BI2: =BG2 -> 1
A3: 2 | B3: 44671.042 | C3: 1 | D3: 44671.042 | E3: 1 | F3: 44671.042 | G3: 1 | H3: 44671.042 | I3: 1 | J3: 44671.042 | K3: 1 | L3: =J3 -> 44671.042 | M3: =K3 -> 1 | N3: =L3 -> 44671.042 | O3: =M3 -> 1 | P3: =N3 -> 44671.042 | Q3: =O3 -> 1 | R3: =P3 -> 44671.042 | S3: =Q3 -> 1 | ... BI3: =BG3 -> 1
A4: 3
A5: 4
A6: 5
A7: 6
A8: 7
A9: 8
A10: 9
A11: 10
A12: 11
A13: 12
A14: 13
A15: 14
... A25: 24

Sheet node_delay
A1: node1 | B1: node2 | C1: delay_t | D1: min_flow | E1: max_flow
A2: delay_source | B2: dh_source | C2: 2 | D2: 0 | E2: 1000

Sheet node_diffusion
A1: t | B1: dh_sto,ambience,s1 | C1: dh_sto,ambience,s2 | D1: dh_sto,ambience,s3 | E1: dh_sto,ambience,s4 | F1: dh_sto,ambience,s5 | G1: dh_sto,ambience,s6 | H1: dh_sto,ambience,s7 | I1: dh_sto,ambience,s8 | J1: dh_sto,ambience,s9 | K1: dh_sto,ambience,s10 | L1: dh_sto,ambience,s11 | M1: dh_sto,ambience,s12 | N1: dh_sto,ambience,s13 | O1: dh_sto,ambience,s14 | P1: dh_sto,ambience,s15 | Q1: dh_sto,ambience,s16 | R1: dh_sto,ambience,s17 | S1: dh_sto,ambience,s18 | T1: dh_sto,ambience,s19 | U1: dh_sto,ambience,s20 | V1: dh_sto,ambience,s21 | W1: dh_sto,ambience,s22 | X1: dh_sto,ambience,s23 | Y1: dh_sto,ambience,s24 | Z1: dh_sto,ambience,s25 | AA1: dh_sto,ambience,s26 | AB1: dh_sto,ambience,s27 | AC1: dh_sto,ambience,s28 | AD1: dh_sto,ambience,s29 | AE1: dh_sto,ambience,s30
A2: =IF(timeseries!A2<>"",timeseries!A2,"") -> 44671 | B2: 0.02 | C2: 0.02 | D2: 0.02 | E2: 0.02 | F2: 0.02 | G2: 0.02 | H2: 0.02 | I2: 0.02 | J2: 0.02 | K2: 0.02 | L2: 0.02 | M2: 0.02 | N2: 0.02 | O2: 0.02 | P2: 0.02 | Q2: 0.02 | R2: 0.02 | S2: 0.02 | T2: 0.02 | U2: 0.02 | V2: 0.02 | W2: 0.02 | X2: 0.02 | Y2: 0.02 | Z2: 0.02 | AA2: 0.02 | AB2: 0.02 | AC2: 0.02 | AD2: 0.02 | AE2: 0.02
A3: =IF(timeseries!A3<>"",timeseries!A3,"") -> 44671.042 | B3: 0.02 | C3: 0.02 | D3: 0.02 | E3: 0.02 | F3: 0.02 | G3: 0.02 | H3: 0.02 | I3: 0.02 | J3: 0.02 | K3: 0.02 | L3: 0.02 | M3: 0.02 | N3: 0.02 | O3: 0.02 | P3: 0.02 | Q3: 0.02 | R3: 0.02 | S3: 0.02 | T3: 0.02 | U3: 0.02 | V3: 0.02 | W3: 0.02 | X3: 0.02 | Y3: 0.02 | Z3: 0.02 | AA3: 0.02 | AB3: 0.02 | AC3: 0.02 | AD3: 0.02 | AE3: 0.02
A4: =IF(timeseries!A4<>"",timeseries!A4,"") -> 44671.083 | B4: 0.02 | C4: 0.02 | D4: 0.02 | E4: 0.02 | F4: 0.02 | G4: 0.02 | H4: 0.02 | I4: 0.02 | J4: 0.02 | K4: 0.02 | L4: 0.02 | M4: 0.02 | N4: 0.02 | O4: 0.02 | P4: 0.02 | Q4: 0.02 | R4: 0.02 | S4: 0.02 | T4: 0.02 | U4: 0.02 | V4: 0.02 | W4: 0.02 | X4: 0.02 | Y4: 0.02 | Z4: 0.02 | AA4: 0.02 | AB4: 0.02 | AC4: 0.02 | AD4: 0.02 | AE4: 0.02
A5: =IF(timeseries!A5<>"",timeseries!A5,"") -> 44671.125 | B5: 0.02 | C5: 0.02 | D5: 0.02 | E5: 0.02 | F5: 0.02 | G5: 0.02 | H5: 0.02 | I5: 0.02 | J5: 0.02 | K5: 0.02 | L5: 0.02 | M5: 0.02 | N5: 0.02 | O5: 0.02 | P5: 0.02 | Q5: 0.02 | R5: 0.02 | S5: 0.02 | T5: 0.02 | U5: 0.02 | V5: 0.02 | W5: 0.02 | X5: 0.02 | Y5: 0.02 | Z5: 0.02 | AA5: 0.02 | AB5: 0.02 | AC5: 0.02 | AD5: 0.02 | AE5: 0.02
A6: =IF(timeseries!A6<>"",timeseries!A6,"") -> 44671.167 | B6: 0.02 | C6: 0.02 | D6: 0.02 | E6: 0.02 | F6: 0.02 | G6: 0.02 | H6: 0.02 | I6: 0.02 | J6: 0.02 | K6: 0.02 | L6: 0.02 | M6: 0.02 | N6: 0.02 | O6: 0.02 | P6: 0.02 | Q6: 0.02 | R6: 0.02 | S6: 0.02 | T6: 0.02 | U6: 0.02 | V6: 0.02 | W6: 0.02 | X6: 0.02 | Y6: 0.02 | Z6: 0.02 | AA6: 0.02 | AB6: 0.02 | AC6: 0.02 | AD6: 0.02 | AE6: 0.02
A7: =IF(timeseries!A7<>"",timeseries!A7,"") -> 44671.208 | B7: 0.02 | C7: 0.02 | D7: 0.02 | E7: 0.02 | F7: 0.02 | G7: 0.02 | H7: 0.02 | I7: 0.02 | J7: 0.02 | K7: 0.02 | L7: 0.02 | M7: 0.02 | N7: 0.02 | O7: 0.02 | P7: 0.02 | Q7: 0.02 | R7: 0.02 | S7: 0.02 | T7: 0.02 | U7: 0.02 | V7: 0.02 | W7: 0.02 | X7: 0.02 | Y7: 0.02 | Z7: 0.02 | AA7: 0.02 | AB7: 0.02 | AC7: 0.02 | AD7: 0.02 | AE7: 0.02
A8: =IF(timeseries!A8<>"",timeseries!A8,"") -> 44671.25 | B8: 0.02 | C8: 0.02 | D8: 0.02 | E8: 0.02 | F8: 0.02 | G8: 0.02 | H8: 0.02 | I8: 0.02 | J8: 0.02 | K8: 0.02 | L8: 0.02 | M8: 0.02 | N8: 0.02 | O8: 0.02 | P8: 0.02 | Q8: 0.02 | R8: 0.02 | S8: 0.02 | T8: 0.02 | U8: 0.02 | V8: 0.02 | W8: 0.02 | X8: 0.02 | Y8: 0.02 | Z8: 0.02 | AA8: 0.02 | AB8: 0.02 | AC8: 0.02 | AD8: 0.02 | AE8: 0.02
A9: =IF(timeseries!A9<>"",timeseries!A9,"") -> 44671.292 | B9: 0.02 | C9: 0.02 | D9: 0.02 | E9: 0.02 | F9: 0.02 | G9: 0.02 | H9: 0.02 | I9: 0.02 | J9: 0.02 | K9: 0.02 | L9: 0.02 | M9: 0.02 | N9: 0.02 | O9: 0.02 | P9: 0.02 | Q9: 0.02 | R9: 0.02 | S9: 0.02 | T9: 0.02 | U9: 0.02 | V9: 0.02 | W9: 0.02 | X9: 0.02 | Y9: 0.02 | Z9: 0.02 | AA9: 0.02 | AB9: 0.02 | AC9: 0.02 | AD9: 0.02 | AE9: 0.02
A10: =IF(timeseries!A10<>"",timeseries!A10,"") -> 44671.333 | B10: 0.02 | C10: 0.02 | D10: 0.02 | E10: 0.02 | F10: 0.02 | G10: 0.02 | H10: 0.02 | I10: 0.02 | J10: 0.02 | K10: 0.02 | L10: 0.02 | M10: 0.02 | N10: 0.02 | O10: 0.02 | P10: 0.02 | Q10: 0.02 | R10: 0.02 | S10: 0.02 | T10: 0.02 | U10: 0.02 | V10: 0.02 | W10: 0.02 | X10: 0.02 | Y10: 0.02 | Z10: 0.02 | AA10: 0.02 | AB10: 0.02 | AC10: 0.02 | AD10: 0.02 | AE10: 0.02
A11: =IF(timeseries!A11<>"",timeseries!A11,"") -> 44671.375 | B11: 0.02 | C11: 0.02 | D11: 0.02 | E11: 0.02 | F11: 0.02 | G11: 0.02 | H11: 0.02 | I11: 0.02 | J11: 0.02 | K11: 0.02 | L11: 0.02 | M11: 0.02 | N11: 0.02 | O11: 0.02 | P11: 0.02 | Q11: 0.02 | R11: 0.02 | S11: 0.02 | T11: 0.02 | U11: 0.02 | V11: 0.02 | W11: 0.02 | X11: 0.02 | Y11: 0.02 | Z11: 0.02 | AA11: 0.02 | AB11: 0.02 | AC11: 0.02 | AD11: 0.02 | AE11: 0.02
A12: =IF(timeseries!A12<>"",timeseries!A12,"") -> 44671.417 | B12: 0.02 | C12: 0.02 | D12: 0.02 | E12: 0.02 | F12: 0.02 | G12: 0.02 | H12: 0.02 | I12: 0.02 | J12: 0.02 | K12: 0.02 | L12: 0.02 | M12: 0.02 | N12: 0.02 | O12: 0.02 | P12: 0.02 | Q12: 0.02 | R12: 0.02 | S12: 0.02 | T12: 0.02 | U12: 0.02 | V12: 0.02 | W12: 0.02 | X12: 0.02 | Y12: 0.02 | Z12: 0.02 | AA12: 0.02 | AB12: 0.02 | AC12: 0.02 | AD12: 0.02 | AE12: 0.02
A13: =IF(timeseries!A13<>"",timeseries!A13,"") -> 44671.458 | B13: 0.02 | C13: 0.02 | D13: 0.02 | E13: 0.02 | F13: 0.02 | G13: 0.02 | H13: 0.02 | I13: 0.02 | J13: 0.02 | K13: 0.02 | L13: 0.02 | M13: 0.02 | N13: 0.02 | O13: 0.02 | P13: 0.02 | Q13: 0.02 | R13: 0.02 | S13: 0.02 | T13: 0.02 | U13: 0.02 | V13: 0.02 | W13: 0.02 | X13: 0.02 | Y13: 0.02 | Z13: 0.02 | AA13: 0.02 | AB13: 0.02 | AC13: 0.02 | AD13: 0.02 | AE13: 0.02
... A481: =IF(timeseries!A481<>"",timeseries!A481,"") -> 44690.958 | B481: 0.02 | C481: 0.02 | D481: 0.02 | E481: 0.02 | F481: 0.02 | G481: 0.02 | H481: 0.02 | I481: 0.02 | J481: 0.02 | K481: 0.02 | L481: 0.02 | M481: 0.02 | N481: 0.02 | O481: 0.02 | P481: 0.02 | Q481: 0.02 | R481: 0.02 | S481: 0.02 | T481: 0.02 | U481: 0.02 | V481: 0.02 | W481: 0.02 | X481: 0.02 | Y481: 0.02 | Z481: 0.02 | AA481: 0.02 | AB481: 0.02 | AC481: 0.02 | AD481: 0.02 | AE481: 0.02

Sheet reserve_type
A1: reserve_type | B1: ramp_factor
A2: slow | B2: 1

Sheet cf
A1: t | B1: pv1,ALL
A2: =IF(timeseries!A2<>"",timeseries!A2,"") -> 44671 | B2: 0
A3: =IF(timeseries!A3<>"",timeseries!A3,"") -> 44671.042 | B3: 0.4
A4: =IF(timeseries!A4<>"",timeseries!A4,"") -> 44671.083 | B4: 0.5
A5: =IF(timeseries!A5<>"",timeseries!A5,"") -> 44671.125 | B5: 0.5
A6: =IF(timeseries!A6<>"",timeseries!A6,"") -> 44671.167 | B6: 0.4
A7: =IF(timeseries!A7<>"",timeseries!A7,"") -> 44671.208 | B7: 0.2
A8: =IF(timeseries!A8<>"",timeseries!A8,"") -> 44671.25 | B8: 0.8
A9: =IF(timeseries!A9<>"",timeseries!A9,"") -> 44671.292 | B9: 0.2
A10: =IF(timeseries!A10<>"",timeseries!A10,"") -> 44671.333 | B10: 0.5
A11: =IF(timeseries!A11<>"",timeseries!A11,"") -> 44671.375 | B11: 0.4
A12: =IF(timeseries!A12<>"",timeseries!A12,"") -> 44671.417 | B12: 0
A13: =IF(timeseries!A13<>"",timeseries!A13,"") -> 44671.458 | B13: 0.3
... A481: =IF(timeseries!A481<>"",timeseries!A481,"") -> 44690.958 | B481: 0.6

Sheet inflow
A1: t | B1: dh2,s1 | C1: dh2,s2 | D1: dh2,s3 | E1: dh2,s4 | F1: dh2,s5 | G1: dh2,s6 | H1: dh2,s7 | I1: dh2,s8 | J1: dh2,s9 | K1: dh2,s10 | L1: dh2,s11 | M1: dh2,s12 | N1: dh2,s13 | O1: dh2,s14 | P1: dh2,s15 | Q1: dh2,s16 | R1: dh2,s17 | S1: dh2,s18 | T1: dh2,s19 | U1: dh2,s20 | V1: dh2,s21 | W1: dh2,s22 | X1: dh2,s23 | Y1: dh2,s24 | Z1: dh2,s25 | AA1: dh2,s26 | AB1: dh2,s27 | AC1: dh2,s28 | AD1: dh2,s29 | AE1: dh2,s30 | AF1: h2,s1 | AG1: h2,s2 | AH1: h2,s3 | AI1: h2,s4 | AJ1: h2,s5 | AK1: h2,s6 | AL1: h2,s7 | AM1: h2,s8 | AN1: h2,s9 | AO1: h2,s10 | AP1: h2,s11 | AQ1: h2,s12 | AR1: h2,s13 | AS1: h2,s14 | AT1: h2,s15 | AU1: h2,s16 | AV1: h2,s17 | AW1: h2,s18 | AX1: h2,s19 | AY1: h2,s20 | AZ1: h2,s21 | BA1: h2,s22 | BB1: h2,s23 | BC1: h2,s24 | BD1: h2,s25 | BE1: h2,s26 | BF1: h2,s27 | BG1: h2,s28 | BH1: h2,s29 | BI1: h2,s30 | BJ1: ambience,s1 | BK1: ambience,s2 | BL1: ambience,s3 | BM1: ambience,s4 | BN1: ambience,s5 | BO1: ambience,s6 | BP1: ambience,s7 | BQ1: ambience,s8 | BR1: ambience,s9 | BS1: ambience,s10 | BT1: ambience,s11 | BU1: ambience,s12 | BV1: ambience,s13 | BW1: ambience,s14 | BX1: ambience,s15 | BY1: ambience,s16 | BZ1: ambience,s17 | CA1: ambience,s18 | CB1: ambience,s19 | CC1: ambience,s20 | CD1: ambience,s21 | CE1: ambience,s22 | CF1: ambience,s23 | CG1: ambience,s24 | CH1: ambience,s25 | CI1: ambience,s26 | CJ1: ambience,s27 | CK1: ambience,s28 | CL1: ambience,s29 | CM1: ambience,s30 | CN1: delay_source,s1 | CO1: delay_source,s2 | CP1: delay_source,s3 | CQ1: delay_source,s4 | CR1: delay_source,s5 | CS1: delay_source,s6 | CT1: delay_source,s7 | CU1: delay_source,s8 | CV1: delay_source,s9 | CW1: delay_source,s10 | CX1: delay_source,s11 | CY1: delay_source,s12 | CZ1: delay_source,s13 | DA1: delay_source,s14 | DB1: delay_source,s15 | DC1: delay_source,s16 | DD1: delay_source,s17 | DE1: delay_source,s18 | DF1: delay_source,s19 | DG1: delay_source,s20 | DH1: delay_source,s21 | DI1: delay_source,s22 | DJ1: delay_source,s23 | DK1: delay_source,s24 | DL1: delay_source,s25 | DM1: delay_source,s26 | DN1: delay_source,s27 | DO1: delay_source,s28 | DP1: delay_source,s29 | DQ1: delay_source,s30
A2: 44671 | B2: -5 | C2: -5 | D2: -5 | E2: -5 | F2: -5 | G2: -5 | H2: -5 | I2: -5 | J2: -5 | K2: -5 | L2: -5 | M2: -5 | N2: -5 | O2: -5 | P2: -5 | Q2: -5 | R2: -5 | S2: -5 | T2: -5 | U2: -5 | V2: -5 | W2: -5 | X2: -5 | Y2: -5 | Z2: -5 | AA2: -5 | AB2: -5 | AC2: -5 | AD2: -5 | AE2: -5 | AF2: -5 | AG2: -5 | AH2: -5 | AI2: -5 | AJ2: -5 | AK2: -5 | AL2: -5 | AM2: -5 | AN2: -5 | AO2: -5 | AP2: -5 | AQ2: -5 | AR2: -5 | AS2: -5 | AT2: -5 | AU2: -5 | AV2: -5 | AW2: -5 | AX2: -5 | AY2: -5 | AZ2: -5 | BA2: -5 | BB2: -5 | BC2: -5 | BD2: -5 | BE2: -5 | BF2: -5 | BG2: -5 | BH2: -5 | BI2: -5 | BJ2: -1 | BK2: -1 | BL2: -1 | BM2: -1 | BN2: -1 | BO2: -1 | BP2: -1 | BQ2: -1 | BR2: -1 | BS2: -1 | BT2: -1 | BU2: -1 | BV2: -1 | BW2: -1 | BX2: -1 | BY2: -1 | BZ2: -1 | CA2: -1 | CB2: -1 | CC2: -1 | CD2: -1 | CE2: -1 | CF2: -1 | CG2: -1 | CH2: -1 | CI2: -1 | CJ2: -1 | CK2: -1 | CL2: -1 | CM2: -1 | CN2: 1 | CO2: 1 | CP2: 1 | CQ2: 1 | CR2: 1 | CS2: 1 | CT2: 1 | CU2: 1 | CV2: 1 | CW2: 1 | CX2: 1 | CY2: 1 | CZ2: 1 | DA2: 1 | DB2: 1 | DC2: 1 | DD2: 1 | DE2: 1 | DF2: 1 | DG2: 1 | DH2: 1 | DI2: 1 | DJ2: 1 | DK2: 1 | DL2: 1 | DM2: 1 | DN2: 1 | DO2: 1 | DP2: 1 | DQ2: 1
A3: 44671.042 | B3: -5 | C3: -5 | D3: -5 | E3: -5 | F3: -5 | G3: -5 | H3: -5 | I3: -5 | J3: -5 | K3: -5 | L3: -5 | M3: -5 | N3: -5 | O3: -5 | P3: -5 | Q3: -5 | R3: -5 | S3: -5 | T3: -5 | U3: -5 | V3: -5 | W3: -5 | X3: -5 | Y3: -5 | Z3: -5 | AA3: -5 | AB3: -5 | AC3: -5 | AD3: -5 | AE3: -5 | AF3: -5 | AG3: -5 | AH3: -5 | AI3: -5 | AJ3: -5 | AK3: -5 | AL3: -5 | AM3: -5 | AN3: -5 | AO3: -5 | AP3: -5 | AQ3: -5 | AR3: -5 | AS3: -5 | AT3: -5 | AU3: -5 | AV3: -5 | AW3: -5 | AX3: -5 | AY3: -5 | AZ3: -5 | BA3: -5 | BB3: -5 | BC3: -5 | BD3: -5 | BE3: -5 | BF3: -5 | BG3: -5 | BH3: -5 | BI3: -5 | BJ3: 0 | BK3: 0 | BL3: 0 | BM3: 0 | BN3: 0 | BO3: 0 | BP3: 0 | BQ3: 0 | BR3: 0 | BS3: 0 | BT3: 0 | BU3: 0 | BV3: 0 | BW3: 0 | BX3: 0 | BY3: 0 | BZ3: 0 | CA3: 0 | CB3: 0 | CC3: 0 | CD3: 0 | CE3: 0 | CF3: 0 | CG3: 0 | CH3: 0 | CI3: 0 | CJ3: 0 | CK3: 0 | CL3: 0 | CM3: 0 | CN3: 1 | CO3: 1 | CP3: 1 | CQ3: 1 | CR3: 1 | CS3: 1 | CT3: 1 | CU3: 1 | CV3: 1 | CW3: 1 | CX3: 1 | CY3: 1 | CZ3: 1 | DA3: 1 | DB3: 1 | DC3: 1 | DD3: 1 | DE3: 1 | DF3: 1 | DG3: 1 | DH3: 1 | DI3: 1 | DJ3: 1 | DK3: 1 | DL3: 1 | DM3: 1 | DN3: 1 | DO3: 1 | DP3: 1 | DQ3: 1
A4: 44671.083 | B4: -4 | C4: -4 | D4: -4 | E4: -4 | F4: -4 | G4: -4 | H4: -4 | I4: -4 | J4: -4 | K4: -4 | L4: -4 | M4: -4 | N4: -4 | O4: -4 | P4: -4 | Q4: -4 | R4: -4 | S4: -4 | T4: -4 | U4: -4 | V4: -4 | W4: -4 | X4: -4 | Y4: -4 | Z4: -4 | AA4: -4 | AB4: -4 | AC4: -4 | AD4: -4 | AE4: -4 | AF4: -6 | AG4: -6 | AH4: -6 | AI4: -6 | AJ4: -6 | AK4: -6 | AL4: -6 | AM4: -6 | AN4: -6 | AO4: -6 | AP4: -6 | AQ4: -6 | AR4: -6 | AS4: -6 | AT4: -6 | AU4: -6 | AV4: -6 | AW4: -6 | AX4: -6 | AY4: -6 | AZ4: -6 | BA4: -6 | BB4: -6 | BC4: -6 | BD4: -6 | BE4: -6 | BF4: -6 | BG4: -6 | BH4: -6 | BI4: -6 | BJ4: -2 | BK4: 0 | BL4: 0 | BM4: 0 | BN4: 0 | BO4: 0 | BP4: 0 | BQ4: 0 | BR4: 0 | BS4: 0 | BT4: 0 | BU4: 0 | BV4: 0 | BW4: 0 | BX4: 0 | BY4: 0 | BZ4: 0 | CA4: 0 | CB4: 0 | CC4: 0 | CD4: 0 | CE4: 0 | CF4: 0 | CG4: 0 | CH4: 0 | CI4: 0 | CJ4: 0 | CK4: 0 | CL4: 0 | CM4: 0 | CN4: 2 | CO4: 2 | CP4: 2 | CQ4: 2 | CR4: 2 | CS4: 2 | CT4: 2 | CU4: 2 | CV4: 2 | CW4: 2 | CX4: 2 | CY4: 2 | CZ4: 2 | DA4: 2 | DB4: 2 | DC4: 2 | DD4: 2 | DE4: 2 | DF4: 2 | DG4: 2 | DH4: 2 | DI4: 2 | DJ4: 2 | DK4: 2 | DL4: 2 | DM4: 2 | DN4: 2 | DO4: 2 | DP4: 2 | DQ4: 2
A5: 44671.125 | B5: -6 | C5: -2 | D5: -1 | E5: -6 | F5: -4 | G5: -5 | H5: -5 | I5: -6 | J5: -3 | K5: -3 | L5: -2 | M5: -4 | N5: -6 | O5: -5 | P5: -2 | Q5: -6 | R5: -3 | S5: -2 | T5: -2 | U5: -6 | V5: -3 | W5: -4 | X5: -3 | Y5: -2 | Z5: -6 | AA5: -3 | AB5: -2 | AC5: -4 | AD5: -3 | AE5: -4 | AF5: -3 | AG5: -5 | AH5: -4 | AI5: -6 | AJ5: -6 | AK5: -4 | AL5: -8 | AM5: -5 | AN5: -8 | AO5: -7 | AP5: -4 | AQ5: -6 | AR5: -7 | AS5: -8 | AT5: -8 | AU5: -4 | AV5: -6 | AW5: -5 | AX5: -5 | AY5: -5 | AZ5: -8 | BA5: -6 | BB5: -5 | BC5: -6 | BD5: -8 | BE5: -7 | BF5: -4 | BG5: -8 | BH5: -6 | BI5: -4 | BJ5: 0 | BK5: 0 | BL5: 0 | BM5: 0 | BN5: 0 | BO5: 0 | BP5: 0 | BQ5: 0 | BR5: 0 | BS5: 0 | BT5: 0 | BU5: 0 | BV5: 0 | BW5: 0 | BX5: 0 | BY5: 0 | BZ5: 0 | CA5: 0 | CB5: 0 | CC5: 0 | CD5: 0 | CE5: 0 | CF5: 0 | CG5: 0 | CH5: 0 | CI5: 0 | CJ5: 0 | CK5: 0 | CL5: 0 | CM5: 0 | CN5: 1 | CO5: 3 | CP5: 4 | CQ5: 3 | CR5: 1 | CS5: 1 | CT5: 0 | CU5: 4 | CV5: 3 | CW5: 2 | CX5: 1 | CY5: 1 | CZ5: 2 | DA5: 3 | DB5: 0 | DC5: 4 | DD5: 2 | DE5: 3 | DF5: 0 | DG5: 3 | DH5: 0 | DI5: 4 | DJ5: 4 | DK5: 3 | DL5: 3 | DM5: 2 | DN5: 3 | DO5: 3 | DP5: 1 | DQ5: 0
A6: 44671.167 | B6: -7 | C6: -7 | D6: -2 | E6: -7 | F6: -3 | G6: -6 | H6: -7 | I6: -6 | J6: -1 | K6: -3 | L6: -1 | M6: -6 | N6: -6 | O6: -3 | P6: -3 | Q6: -5 | R6: -2 | S6: -1 | T6: -1 | U6: -7 | V6: -3 | W6: -2 | X6: -5 | Y6: -4 | Z6: -5 | AA6: -3 | AB6: -2 | AC6: -2 | AD6: -4 | AE6: -5 | AF6: -4 | AG6: -7 | AH6: -4 | AI6: -5 | AJ6: -5 | AK6: -2 | AL6: -8 | AM6: -4 | AN6: -6 | AO6: -8 | AP6: -4 | AQ6: -6 | AR6: -8 | AS6: -8 | AT6: -8 | AU6: -2 | AV6: -7 | AW6: -3 | AX6: -7 | AY6: -4 | AZ6: -6 | BA6: -8 | BB6: -3 | BC6: -5 | BD6: -8 | BE6: -8 | BF6: -3 | BG6: -8 | BH6: -7 | BI6: -4 | BJ6: 0 | BK6: 0 | BL6: 0 | BM6: 0 | BN6: 0 | BO6: 0 | BP6: 0 | BQ6: 0 | BR6: 0 | BS6: 0 | BT6: 0 | BU6: 0 | BV6: 0 | BW6: 0 | BX6: 0 | BY6: 0 | BZ6: 0 | CA6: 0 | CB6: 0 | CC6: 0 | CD6: 0 | CE6: 0 | CF6: 0 | CG6: 0 | CH6: 0 | CI6: 0 | CJ6: 0 | CK6: 0 | CL6: 0 | CM6: 0 | CN6: 1 | CO6: 2 | CP6: 2 | CQ6: 2 | CR6: 4 | CS6: 3 | CT6: 4 | CU6: 4 | CV6: 0 | CW6: 3 | CX6: 4 | CY6: 2 | CZ6: 2 | DA6: 0 | DB6: 2 | DC6: 0 | DD6: 2 | DE6: 0 | DF6: 3 | DG6: 2 | DH6: 0 | DI6: 1 | DJ6: 1 | DK6: 2 | DL6: 0 | DM6: 4 | DN6: 4 | DO6: 1 | DP6: 4 | DQ6: 0
A7: 44671.208 | B7: -3 | C7: -7 | D7: -4 | E7: -8 | F7: -3 | G7: -7 | H7: -7 | I7: -8 | J7: -2 | K7: -3 | L7: -2 | M7: -4 | N7: -8 | O7: -5 | P7: -2 | Q7: -4 | R7: -4 | S7: -3 | T7: -1 | U7: -6 | V7: -1 | W7: -4 | X7: -3 | Y7: -6 | Z7: -5 | AA7: -4 | AB7: -3 | AC7: -1 | AD7: -4 | AE7: -5 | AF7: -2 | AG7: -1 | AH7: -4 | AI7: -6 | AJ7: -5 | AK7: -4 | AL7: -8 | AM7: -2 | AN7: -4 | AO7: -7 | AP7: -4 | AQ7: -6 | AR7: -6 | AS7: -6 | AT7: -6 | AU7: -1 | AV7: -5 | AW7: -3 | AX7: -7 | AY7: -5 | AZ7: -4 | BA7: -6 | BB7: -3 | BC7: -7 | BD7: -8 | BE7: -6 | BF7: -2 | BG7: -7 | BH7: -8 | BI7: -2 | BJ7: 0 | BK7: 0 | BL7: 0 | BM7: 0 | BN7: 0 | BO7: 0 | BP7: 0 | BQ7: 0 | BR7: 0 | BS7: 0 | BT7: 0 | BU7: 0 | BV7: 0 | BW7: 0 | BX7: 0 | BY7: 0 | BZ7: 0 | CA7: 0 | CB7: 0 | CC7: 0 | CD7: 0 | CE7: 0 | CF7: 0 | CG7: 0 | CH7: 0 | CI7: 0 | CJ7: 0 | CK7: 0 | CL7: 0 | CM7: 0 | CN7: 3 | CO7: 2 | CP7: 3 | CQ7: 0 | CR7: 4 | CS7: 3 | CT7: 1 | CU7: 1 | CV7: 4 | CW7: 4 | CX7: 2 | CY7: 4 | CZ7: 0 | DA7: 4 | DB7: 1 | DC7: 0 | DD7: 4 | DE7: 2 | DF7: 1 | DG7: 0 | DH7: 1 | DI7: 4 | DJ7: 2 | DK7: 2 | DL7: 3 | DM7: 1 | DN7: 3 | DO7: 1 | DP7: 1 | DQ7: 0
A8: 44671.25 | B8: -5 | C8: -5 | D8: -3 | E8: -8 | F8: -1 | G8: -8 | H8: -8 | I8: -8 | J8: -1 | K8: -3 | L8: -3 | M8: -4 | N8: -8 | O8: -5 | P8: -1 | Q8: -3 | R8: -4 | S8: -4 | T8: -3 | U8: -6 | V8: -1 | W8: -2 | X8: -3 | Y8: -5 | Z8: -3 | AA8: -5 | AB8: -5 | AC8: -2 | AD8: -3 | AE8: -6 | AF8: -1 | AG8: -4 | AH8: -3 | AI8: -8 | AJ8: -3 | AK8: -3 | AL8: -7 | AM8: -4 | AN8: -5 | AO8: -7 | AP8: -5 | AQ8: -5 | AR8: -5 | AS8: -5 | AT8: -7 | AU8: -3 | AV8: -4 | AW8: -5 | AX8: -8 | AY8: -3 | AZ8: -2 | BA8: -5 | BB8: -2 | BC8: -5 | BD8: -7 | BE8: -5 | BF8: -3 | BG8: -7 | BH8: -8 | BI8: -1 | BJ8: 0 | BK8: 0 | BL8: 0 | BM8: 0 | BN8: 0 | BO8: 0 | BP8: 0 | BQ8: 0 | BR8: 0 | BS8: 0 | BT8: 0 | BU8: 0 | BV8: 0 | BW8: 0 | BX8: 0 | BY8: 0 | BZ8: 0 | CA8: 0 | CB8: 0 | CC8: 0 | CD8: 0 | CE8: 0 | CF8: 0 | CG8: 0 | CH8: 0 | CI8: 0 | CJ8: 0 | CK8: 0 | CL8: 0 | CM8: 0 | CN8: 3 | CO8: 2 | CP8: 2 | CQ8: 4 | CR8: 2 | CS8: 2 | CT8: 2 | CU8: 4 | CV8: 0 | CW8: 4 | CX8: 4 | CY8: 2 | CZ8: 3 | DA8: 3 | DB8: 2 | DC8: 0 | DD8: 0 | DE8: 0 | DF8: 0 | DG8: 0 | DH8: 1 | DI8: 3 | DJ8: 4 | DK8: 4 | DL8: 3 | DM8: 2 | DN8: 4 | DO8: 3 | DP8: 1 | DQ8: 3
A9: 44671.292 | B9: -4 | C9: -1 | D9: -7 | E9: -7 | F9: -2 | G9: -8 | H9: -8 | I9: -8 | J9: -1 | K9: -4 | L9: -5 | M9: -4 | N9: -8 | O9: -5 | P9: -1 | Q9: -1 | R9: -4 | S9: -5 | T9: -4 | U9: -8 | V9: -1 | W9: -1 | X9: -1 | Y9: -6 | Z9: -4 | AA9: -6 | AB9: -7 | AC9: -1 | AD9: -2 | AE9: -4 | AF9: -6 | AG9: -1 | AH9: -7 | AI9: -6 | AJ9: -3 | AK9: -1 | AL9: -7 | AM9: -6 | AN9: -7 | AO9: -8 | AP9: -5 | AQ9: -4 | AR9: -4 | AS9: -3 | AT9: -7 | AU9: -1 | AV9: -4 | AW9: -4 | AX9: -7 | AY9: -2 | AZ9: -1 | BA9: -7 | BB9: -3 | BC9: -7 | BD9: -6 | BE9: -6 | BF9: -1 | BG9: -5 | BH9: -8 | BI9: -3 | BJ9: 0 | BK9: 0 | BL9: 0 | BM9: 0 | BN9: 0 | BO9: 0 | BP9: 0 | BQ9: 0 | BR9: 0 | BS9: 0 | BT9: 0 | BU9: 0 | BV9: 0 | BW9: 0 | BX9: 0 | BY9: 0 | BZ9: 0 | CA9: 0 | CB9: 0 | CC9: 0 | CD9: 0 | CE9: 0 | CF9: 0 | CG9: 0 | CH9: 0 | CI9: 0 | CJ9: 0 | CK9: 0 | CL9: 0 | CM9: 0 | CN9: 0 | CO9: 2 | CP9: 1 | CQ9: 4 | CR9: 3 | CS9: 2 | CT9: 2 | CU9: 2 | CV9: 1 | CW9: 2 | CX9: 3 | CY9: 2 | CZ9: 3 | DA9: 1 | DB9: 1 | DC9: 2 | DD9: 3 | DE9: 1 | DF9: 4 | DG9: 3 | DH9: 2 | DI9: 0 | DJ9: 2 | DK9: 0 | DL9: 0 | DM9: 2 | DN9: 4 | DO9: 1 | DP9: 2 | DQ9: 3
A10: 44671.333 | B10: -4 | C10: -7 | D10: -6 | E10: -8 | F10: -3 | G10: -7 | H10: -6 | I10: -7 | J10: -2 | K10: -3 | L10: -6 | M10: -2 | N10: -8 | O10: -7 | P10: -2 | Q10: -2 | R10: -5 | S10: -4 | T10: -2 | U10: -7 | V10: -1 | W10: -1 | X10: -3 | Y10: -6 | Z10: -3 | AA10: -7 | AB10: -8 | AC10: -3 | AD10: -3 | AE10: -3 | AF10: -5 | AG10: -4 | AH10: -4 | AI10: -6 | AJ10: -2 | AK10: -2 | AL10: -7 | AM10: -8 | AN10: -5 | AO10: -8 | AP10: -3 | AQ10: -6 | AR10: -6 | AS10: -1 | AT10: -8 | AU10: -1 | AV10: -4 | AW10: -4 | AX10: -6 | AY10: -1 | AZ10: -1 | BA10: -7 | BB10: -5 | BC10: -5 | BD10: -6 | BE10: -5 | BF10: -2 | BG10: -3 | BH10: -8 | BI10: -5 | BJ10: 0 | BK10: 0 | BL10: 0 | BM10: 0 | BN10: 0 | BO10: 0 | BP10: 0 | BQ10: 0 | BR10: 0 | BS10: 0 | BT10: 0 | BU10: 0 | BV10: 0 | BW10: 0 | BX10: 0 | BY10: 0 | BZ10: 0 | CA10: 0 | CB10: 0 | CC10: 0 | CD10: 0 | CE10: 0 | CF10: 0 | CG10: 0 | CH10: 0 | CI10: 0 | CJ10: 0 | CK10: 0 | CL10: 0 | CM10: 0 | CN10: 4 | CO10: 0 | CP10: 1 | CQ10: 0 | CR10: 4 | CS10: 4 | CT10: 3 | CU10: 3 | CV10: 2 | CW10: 3 | CX10: 4 | CY10: 1 | CZ10: 3 | DA10: 4 | DB10: 4 | DC10: 3 | DD10: 1 | DE10: 0 | DF10: 4 | DG10: 3 | DH10: 1 | DI10: 3 | DJ10: 0 | DK10: 4 | DL10: 4 | DM10: 4 | DN10: 2 | DO10: 1 | DP10: 3 | DQ10: 0
A11: 44671.375 | B11: -3 | C11: -7 | D11: -1 | E11: -6 | F11: -1 | G11: -6 | H11: -7 | I11: -8 | J11: -1 | K11: -1 | L11: -4 | M11: -4 | N11: -8 | O11: -8 | P11: -3 | Q11: -1 | R11: -5 | S11: -4 | T11: -3 | U11: -5 | V11: -2 | W11: -1 | X11: -5 | Y11: -4 | Z11: -4 | AA11: -7 | AB11: -8 | AC11: -4 | AD11: -2 | AE11: -5 | AF11: -4 | AG11: -5 | AH11: -7 | AI11: -5 | AJ11: -3 | AK11: -1 | AL11: -5 | AM11: -6 | AN11: -6 | AO11: -8 | AP11: -3 | AQ11: -8 | AR11: -7 | AS11: -2 | AT11: -8 | AU11: -1 | AV11: -3 | AW11: -3 | AX11: -7 | AY11: -3 | AZ11: -1 | BA11: -6 | BB11: -3 | BC11: -6 | BD11: -8 | BE11: -6 | BF11: -3 | BG11: -3 | BH11: -8 | BI11: -7 | BJ11: 0 | BK11: 0 | BL11: 0 | BM11: 0 | BN11: 0 | BO11: 0 | BP11: 0 | BQ11: 0 | BR11: 0 | BS11: 0 | BT11: 0 | BU11: 0 | BV11: 0 | BW11: 0 | BX11: 0 | BY11: 0 | BZ11: 0 | CA11: 0 | CB11: 0 | CC11: 0 | CD11: 0 | CE11: 0 | CF11: 0 | CG11: 0 | CH11: 0 | CI11: 0 | CJ11: 0 | CK11: 0 | CL11: 0 | CM11: 0 | CN11: 1 | CO11: 2 | CP11: 3 | CQ11: 3 | CR11: 4 | CS11: 0 | CT11: 0 | CU11: 0 | CV11: 1 | CW11: 3 | CX11: 4 | CY11: 1 | CZ11: 3 | DA11: 0 | DB11: 1 | DC11: 4 | DD11: 3 | DE11: 2 | DF11: 4 | DG11: 4 | DH11: 0 | DI11: 2 | DJ11: 0 | DK11: 4 | DL11: 3 | DM11: 0 | DN11: 1 | DO11: 0 | DP11: 1 | DQ11: 1
A12: 44671.417 | B12: -6 | C12: -7 | D12: -3 | E12: -5 | F12: -1 | G12: -6 | H12: -7 | I12: -6 | J12: -2 | K12: -1 | L12: -2 | M12: -2 | N12: -8 | O12: -8 | P12: -4 | Q12: -1 | R12: -5 | S12: -2 | T12: -3 | U12: -4 | V12: -1 | W12: -1 | X12: -4 | Y12: -3 | Z12: -6 | AA12: -5 | AB12: -8 | AC12: -6 | AD12: -4 | AE12: -7 | AF12: -5 | AG12: -1 | AH12: -4 | AI12: -5 | AJ12: -2 | AK12: -1 | AL12: -6 | AM12: -5 | AN12: -5 | AO12: -7 | AP12: -2 | AQ12: -6 | AR12: -5 | AS12: -3 | AT12: -8 | AU12: -1 | AV12: -5 | AW12: -5 | AX12: -8 | AY12: -3 | AZ12: -1 | BA12: -8 | BB12: -5 | BC12: -7 | BD12: -8 | BE12: -5 | BF12: -5 | BG12: -4 | BH12: -8 | BI12: -6 | BJ12: 0 | BK12: 0 | BL12: 0 | BM12: 0 | BN12: 0 | BO12: 0 | BP12: 0 | BQ12: 0 | BR12: 0 | BS12: 0 | BT12: 0 | BU12: 0 | BV12: 0 | BW12: 0 | BX12: 0 | BY12: 0 | BZ12: 0 | CA12: 0 | CB12: 0 | CC12: 0 | CD12: 0 | CE12: 0 | CF12: 0 | CG12: 0 | CH12: 0 | CI12: 0 | CJ12: 0 | CK12: 0 | CL12: 0 | CM12: 0 | CN12: 3 | CO12: 2 | CP12: 0 | CQ12: 4 | CR12: 4 | CS12: 3 | CT12: 0 | CU12: 4 | CV12: 2 | CW12: 1 | CX12: 4 | CY12: 4 | CZ12: 1 | DA12: 1 | DB12: 3 | DC12: 3 | DD12: 4 | DE12: 3 | DF12: 0 | DG12: 4 | DH12: 1 | DI12: 0 | DJ12: 1 | DK12: 4 | DL12: 0 | DM12: 4 | DN12: 3 | DO12: 2 | DP12: 0 | DQ12: 0
A13: 44671.458 | B13: -3 | C13: -6 | D13: -6 | E13: -4 | F13: -2 | G13: -7 | H13: -5 | I13: -7 | J13: -2 | K13: -1 | L13: -1 | M13: -4 | N13: -7 | O13: -8 | P13: -3 | Q13: -1 | R13: -3 | S13: -3 | T13: -4 | U13: -3 | V13: -1 | W13: -1 | X13: -5 | Y13: -3 | Z13: -8 | AA13: -6 | AB13: -8 | AC13: -8 | AD13: -4 | AE13: -5 | AF13: -5 | AG13: -2 | AH13: -7 | AI13: -5 | AJ13: -1 | AK13: -2 | AL13: -4 | AM13: -4 | AN13: -5 | AO13: -5 | AP13: -4 | AQ13: -6 | AR13: -5 | AS13: -3 | AT13: -8 | AU13: -1 | AV13: -6 | AW13: -3 | AX13: -6 | AY13: -2 | AZ13: -1 | BA13: -8 | BB13: -7 | BC13: -8 | BD13: -8 | BE13: -4 | BF13: -4 | BG13: -6 | BH13: -8 | BI13: -6 | BJ13: 0 | BK13: 0 | BL13: 0 | BM13: 0 | BN13: 0 | BO13: 0 | BP13: 0 | BQ13: 0 | BR13: 0 | BS13: 0 | BT13: 0 | BU13: 0 | BV13: 0 | BW13: 0 | BX13: 0 | BY13: 0 | BZ13: 0 | CA13: 0 | CB13: 0 | CC13: 0 | CD13: 0 | CE13: 0 | CF13: 0 | CG13: 0 | CH13: 0 | CI13: 0 | CJ13: 0 | CK13: 0 | CL13: 0 | CM13: 0 | CN13: 3 | CO13: 1 | CP13: 3 | CQ13: 1 | CR13: 2 | CS13: 0 | CT13: 2 | CU13: 1 | CV13: 3 | CW13: 3 | CX13: 3 | CY13: 3 | CZ13: 3 | DA13: 2 | DB13: 1 | DC13: 1 | DD13: 3 | DE13: 2 | DF13: 1 | DG13: 2 | DH13: 4 | DI13: 1 | DJ13: 0 | DK13: 1 | DL13: 4 | DM13: 0 | DN13: 0 | DO13: 4 | DP13: 4 | DQ13: 4
... A481: 44690.958 | B481: -4 | C481: -5 | D481: -4 | E481: -4 | F481: -4 | G481: -3 | H481: -3 | I481: -5 | J481: -5 | K481: -6 | L481: -8 | M481: -1 | N481: -4 | O481: -3 | P481: -4 | Q481: -5 | R481: -3 | S481: -7 | T481: -3 | U481: -4 | V481: -1 | W481: -2 | X481: -1 | Y481: -6 | Z481: -2 | AA481: -4 | AB481: -4 | AC481: -2 | AD481: -7 | AE481: -4 | AF481: -1 | AG481: -2 | AH481: -1 | AI481: -8 | AJ481: -1 | AK481: -1 | AL481: -8 | AM481: -1 | AN481: -1 | AO481: -8 | AP481: -2 | AQ481: -5 | AR481: -5 | AS481: -1 | AT481: -4 | AU481: -8 | AV481: -1 | AW481: -3 | AX481: -5 | AY481: -1 | AZ481: -2 | BA481: -5 | BB481: -8 | BC481: -8 | BD481: -1 | BE481: -2 | BF481: -5 | BG481: -4 | BH481: -1 | BI481: -7 | BJ481: 0 | BK481: 0 | BL481: 0 | BM481: 0 | BN481: 0 | BO481: 0 | BP481: 0 | BQ481: 0 | BR481: 0 | BS481: 0 | BT481: 0 | BU481: 0 | BV481: 0 | BW481: 0 | BX481: 0 | BY481: 0 | BZ481: 0 | CA481: 0 | CB481: 0 | CC481: 0 | CD481: 0 | CE481: 0 | CF481: 0 | CG481: 0 | CH481: 0 | CI481: 0 | CJ481: 0 | CK481: 0 | CL481: 0 | CM481: 0 | CN481: 1 | CO481: 2 | CP481: 4 | CQ481: 1 | CR481: 2 | CS481: 2 | CT481: 2 | CU481: 0 | CV481: 3 | CW481: 1 | CX481: 1 | CY481: 4 | CZ481: 0 | DA481: 2 | DB481: 2 | DC481: 1 | DD481: 2 | DE481: 1 | DF481: 2 | DG481: 4 | DH481: 0 | DI481: 0 | DJ481: 2 | DK481: 1 | DL481: 4 | DM481: 3 | DN481: 4 | DO481: 0 | DP481: 4 | DQ481: 2

Sheet inflow_blocks
A1: t | B1: b1,dh_sto | C1: b1,s1 | D1: b1,s2 | E1: b1,s3 | F1: b1,s4 | G1: b1,s5 | H1: b1,s6 | I1: b1,s7 | J1: b1,s8 | K1: b1,s9 | L1: b1,s10 | M1: b1,s11 | N1: b1,s12 | O1: b1,s13 | P1: b1,s14 | Q1: b1,s15 | R1: b1,s16 | S1: b1,s17 | T1: b1,s18 | U1: b1,s19 | V1: b1,s20 | W1: b1,s21 | X1: b1,s22 | Y1: b1,s23 | Z1: b1,s24 | AA1: b1,s25 | AB1: b1,s26 | AC1: b1,s27 | AD1: b1,s28 | AE1: b1,s29 | AF1: b1,s30
A2: 1 | B2: 44671 | C2: -2 | D2: -3 | E2: -4 | F2: -4.01 | G2: -4.05 | H2: -3.02 | I2: 0.08 | J2: -4.93 | K2: -3.91 | L2: -3.04 | M2: -1.99 | N2: -4.02 | O2: -4.1 | P2: -3.9 | Q2: -2.97 | R2: -0.92 | S2: -5.01 | T2: -5.93 | U2: -0.94 | V2: -2.02 | W2: -2.03 | X2: -3.93 | Y2: -0.96 | Z2: -3.99 | AA2: -1.05 | AB2: -3.06 | AC2: -3.98 | AD2: 0.06 | AE2: -4.9 | AF2: -1.02
A3: 2 | B3: 44671.042 | C3: 1 | D3: 2 | E3: 3 | F3: 3 | G3: 3 | H3: 1 | I3: 0 | J3: 2 | K3: 3 | L3: 3 | M3: 1 | N3: 1 | O3: 2 | P3: 2 | Q3: 3 | R3: 1 | S3: 2 | T3: 3 | U3: 1 | V3: 2 | W3: 0 | X3: 1 | Y3: 0 | Z3: 2 | AA3: 0 | AB3: 0 | AC3: 3 | AD3: 0 | AE3: 3 | AF3: 0
A4: 3 | B4: 44671.083 | C4: 2 | D4: 2 | E4: 2 | F4: 1 | G4: 1 | H4: 2 | I4: 0 | J4: 3 | K4: 1 | L4: 0 | M4: 1 | N4: 3 | O4: 2 | P4: 2 | Q4: 0 | R4: 0 | S4: 3 | T4: 3 | U4: 0 | V4: 0 | W4: 2 | X4: 3 | Y4: 1 | Z4: 2 | AA4: 1 | AB4: 3 | AC4: 1 | AD4: 0 | AE4: 2 | AF4: 1
A5: 4
A6: 5
A7: 6
A8: 7
A9: 8
A10: 9
A11: 10

Sheet flex_inflow
A1: period_name | B1: node | C1: scenario | D1: t_start | E1: t_end | F1: inflow

Sheet price
A1: t | B1: ng, ALL
A2: =IF(timeseries!A2<>"",timeseries!A2,"") -> 44671 | B2: 12
A3: =IF(timeseries!A3<>"",timeseries!A3,"") -> 44671.042 | B3: 12
A4: =IF(timeseries!A4<>"",timeseries!A4,"") -> 44671.083 | B4: 12
A5: =IF(timeseries!A5<>"",timeseries!A5,"") -> 44671.125 | B5: 12
A6: =IF(timeseries!A6<>"",timeseries!A6,"") -> 44671.167 | B6: 12
A7: =IF(timeseries!A7<>"",timeseries!A7,"") -> 44671.208 | B7: 12
A8: =IF(timeseries!A8<>"",timeseries!A8,"") -> 44671.25 | B8: 12
A9: =IF(timeseries!A9<>"",timeseries!A9,"") -> 44671.292 | B9: 12
A10: =IF(timeseries!A10<>"",timeseries!A10,"") -> 44671.333 | B10: 12
A11: =IF(timeseries!A11<>"",timeseries!A11,"") -> 44671.375 | B11: 12
A12: =IF(timeseries!A12<>"",timeseries!A12,"") -> 44671.417 | B12: 12
A13: =IF(timeseries!A13<>"",timeseries!A13,"") -> 44671.458 | B13: 12
... A481: =IF(timeseries!A481<>"",timeseries!A481,"") -> 44690.958 | B481: 12

Sheet markets
A1: market | B1: market_type | C1: node | D1: processgroup | E1: direction | F1: reserve_type | G1: is_bid | H1: is_limited | I1: min_bid | J1: max_bid | K1: fee
A2: npe | B2: energy | C2: elc | D2: p1 | E2: none | F2: none | G2: 1 | H2: 0 | I2: 0 | J2: 0 | K2: 0
A3: fcr_up | B3: reserve | C3: elc_res | D3: p1 | E3: res_up | F3: slow | G3: 1 | H3: 0 | I3: 0 | J3: 0 | K3: 0

Sheet bid_slots
A1: t | B1: npe,p0 | C1: npe,p1 | D1: npe,p2 | E1: npe,p3
A2: =IF(timeseries!A2<>"",timeseries!A2,"") -> 44671 | B2: 40 | C2: 60.001 | D2: 69.001 | E2: 80
A3: =IF(timeseries!A3<>"",timeseries!A3,"") -> 44671.042 | B3: 42 | C3: 58.001 | D3: 69.001 | E3: 85
A4: =IF(timeseries!A4<>"",timeseries!A4,"") -> 44671.083 | B4: 49 | C4: 61.333333 | D4: 73.666667 | E4: 91
A5: =IF(timeseries!A5<>"",timeseries!A5,"") -> 44671.125 | B5: 39 | C5: 53.666667 | D5: 65.333333 | E5: 76
A6: =IF(timeseries!A6<>"",timeseries!A6,"") -> 44671.167 | B6: 39 | C6: 56.001 | D6: 71.001 | E6: 86
A7: =IF(timeseries!A7<>"",timeseries!A7,"") -> 44671.208 | B7: 34 | C7: 53.001 | D7: 75.001 | E7: 96
A8: =IF(timeseries!A8<>"",timeseries!A8,"") -> 44671.25 | B8: 24 | C8: 44.666667 | D8: 66.333333 | E8: 91
A9: =IF(timeseries!A9<>"",timeseries!A9,"") -> 44671.292 | B9: 19 | C9: 42.333333 | D9: 66.666667 | E9: 91
A10: =IF(timeseries!A10<>"",timeseries!A10,"") -> 44671.333 | B10: 24 | C10: 49.333333 | D10: 71.666667 | E10: 96
A11: =IF(timeseries!A11<>"",timeseries!A11,"") -> 44671.375 | B11: 24 | C11: 51.001 | D11: 74.001 | E11: 101
A12: =IF(timeseries!A12<>"",timeseries!A12,"") -> 44671.417 | B12: 14 | C12: 44.001 | D12: 74.001 | E12: 106
A13: =IF(timeseries!A13<>"",timeseries!A13,"") -> 44671.458 | B13: 14 | C13: 46.001 | D13: 76.001 | E13: 106
... A481: =IF(timeseries!A481<>"",timeseries!A481,"") -> 44690.958 | B481: -6 | C481: 38.001 | D481: 84.001 | E481: 131

Sheet reserve_realisation
A1: t | B1: fcr_up,s1 | C1: fcr_up,s2 | D1: fcr_up,s3 | E1: fcr_up,s4 | F1: fcr_up,s5 | G1: fcr_up,s6 | H1: fcr_up,s7 | I1: fcr_up,s8 | J1: fcr_up,s9 | K1: fcr_up,s10 | L1: fcr_up,s11 | M1: fcr_up,s12 | N1: fcr_up,s13 | O1: fcr_up,s14 | P1: fcr_up,s15 | Q1: fcr_up,s16 | R1: fcr_up,s17 | S1: fcr_up,s18 | T1: fcr_up,s19 | U1: fcr_up,s20 | V1: fcr_up,s21 | W1: fcr_up,s22 | X1: fcr_up,s23 | Y1: fcr_up,s24 | Z1: fcr_up,s25 | AA1: fcr_up,s26 | AB1: fcr_up,s27 | AC1: fcr_up,s28 | AD1: fcr_up,s29 | AE1: fcr_up,s30
A2: =IF(timeseries!A2<>"",timeseries!A2,"") -> 44671 | B2: 0.27 | C2: 0.27 | D2: 0.27 | E2: 0.47 | F2: 0.3 | G2: 0.47 | H2: 0.27 | I2: 0.35 | J2: 0.02 | K2: 0.06 | L2: 0.3 | M2: 0.32 | N2: 0.32 | O2: 0.3 | P2: 0.14 | Q2: 0.08 | R2: 0.33 | S2: 0.4 | T2: 0.03 | U2: 0.21 | V2: 0.16 | W2: 0.31 | X2: 0.13 | Y2: 0 | Z2: 0.16 | AA2: 0.08 | AB2: 0.38 | AC2: 0.4 | AD2: 0.2 | AE2: 0.07
A3: =IF(timeseries!A3<>"",timeseries!A3,"") -> 44671.042 | B3: 0.27 | C3: 0.27 | D3: 0.27 | E3: 0.05 | F3: 0.31 | G3: 0.5 | H3: 0.2 | I3: 0.26 | J3: 0.24 | K3: 0.54 | L3: 0.16 | M3: 0.01 | N3: 0.18 | O3: 0.33 | P3: 0.24 | Q3: 0.13 | R3: 0.55 | S3: 0.31 | T3: 0.04 | U3: 0.31 | V3: 0.42 | W3: 0.01 | X3: 0.13 | Y3: 0.28 | Z3: 0.06 | AA3: 0.18 | AB3: 0.22 | AC3: 0.19 | AD3: 0.32 | AE3: 0.25
A4: =IF(timeseries!A4<>"",timeseries!A4,"") -> 44671.083 | B4: 0.27 | C4: 0.29 | D4: 0.31 | E4: 0.11 | F4: 0.37 | G4: 0.04 | H4: 0.36 | I4: 0.49 | J4: 0.01 | K4: 0.24 | L4: 0.17 | M4: 0.15 | N4: 0.23 | O4: 0.03 | P4: 0.04 | Q4: 0.21 | R4: 0.37 | S4: 0.47 | T4: 0.02 | U4: 0.41 | V4: 0.4 | W4: 0.29 | X4: 0.43 | Y4: 0.52 | Z4: 0.46 | AA4: 0.54 | AB4: 0.46 | AC4: 0.43 | AD4: 0.36 | AE4: 0.55
A5: =IF(timeseries!A5<>"",timeseries!A5,"") -> 44671.125 | B5: 0.37 | C5: 0.36 | D5: 0.31 | E5: 0.18 | F5: 0.01 | G5: 0.23 | H5: 0.46 | I5: 0.43 | J5: 0.06 | K5: 0.54 | L5: 0.38 | M5: 0 | N5: 0.23 | O5: 0.15 | P5: 0.38 | Q5: 0.39 | R5: 0.42 | S5: 0.11 | T5: 0.55 | U5: 0.41 | V5: 0.16 | W5: 0.06 | X5: 0.27 | Y5: 0.41 | Z5: 0.34 | AA5: 0.42 | AB5: 0.15 | AC5: 0.23 | AD5: 0.27 | AE5: 0.34
A6: =IF(timeseries!A6<>"",timeseries!A6,"") -> 44671.167 | B6: 0.36 | C6: 0.34 | D6: 0.36 | E6: 0.28 | F6: 0.39 | G6: 0.27 | H6: 0.12 | I6: 0.21 | J6: 0.35 | K6: 0.33 | L6: 0.44 | M6: 0.54 | N6: 0.29 | O6: 0.42 | P6: 0.32 | Q6: 0.27 | R6: 0.46 | S6: 0.01 | T6: 0.07 | U6: 0.31 | V6: 0.24 | W6: 0.32 | X6: 0.44 | Y6: 0.46 | Z6: 0.33 | AA6: 0.49 | AB6: 0.4 | AC6: 0.32 | AD6: 0.29 | AE6: 0.19
A7: =IF(timeseries!A7<>"",timeseries!A7,"") -> 44671.208 | B7: 0.43 | C7: 0.42 | D7: 0.4 | E7: 0.18 | F7: 0.44 | G7: 0.13 | H7: 0.43 | I7: 0.14 | J7: 0.44 | K7: 0.38 | L7: 0.04 | M7: 0.46 | N7: 0.33 | O7: 0.41 | P7: 0 | Q7: 0.55 | R7: 0.23 | S7: 0.51 | T7: 0.25 | U7: 0.13 | V7: 0.09 | W7: 0.1 | X7: 0.18 | Y7: 0.13 | Z7: 0.09 | AA7: 0.35 | AB7: 0.24 | AC7: 0.3 | AD7: 0.44 | AE7: 0.04
A8: =IF(timeseries!A8<>"",timeseries!A8,"") -> 44671.25 | B8: 0.24 | C8: 0.24 | D8: 0.19 | E8: 0.07 | F8: 0.12 | G8: 0.28 | H8: 0.48 | I8: 0.13 | J8: 0.13 | K8: 0.12 | L8: 0.21 | M8: 0.14 | N8: 0.29 | O8: 0.06 | P8: 0.31 | Q8: 0.36 | R8: 0.18 | S8: 0.13 | T8: 0.52 | U8: 0.14 | V8: 0.47 | W8: 0.27 | X8: 0.12 | Y8: 0.42 | Z8: 0.31 | AA8: 0.25 | AB8: 0.08 | AC8: 0.45 | AD8: 0.42 | AE8: 0.1
A9: =IF(timeseries!A9<>"",timeseries!A9,"") -> 44671.292 | B9: 0.22 | C9: 0.22 | D9: 0.25 | E9: 0.17 | F9: 0.4 | G9: 0.45 | H9: 0.21 | I9: 0.17 | J9: 0.22 | K9: 0.06 | L9: 0.22 | M9: 0.32 | N9: 0.51 | O9: 0.36 | P9: 0.05 | Q9: 0.02 | R9: 0.25 | S9: 0.41 | T9: 0.26 | U9: 0.42 | V9: 0.23 | W9: 0.55 | X9: 0.46 | Y9: 0.33 | Z9: 0.24 | AA9: 0.01 | AB9: 0.16 | AC9: 0.29 | AD9: 0.03 | AE9: 0.09
A10: =IF(timeseries!A10<>"",timeseries!A10,"") -> 44671.333 | B10: 0.26 | C10: 0.28 | D10: 0.22 | E10: 0.4 | F10: 0.3 | G10: 0.23 | H10: 0.44 | I10: 0.1 | J10: 0.04 | K10: 0.05 | L10: 0.12 | M10: 0.28 | N10: 0.23 | O10: 0.26 | P10: 0.05 | Q10: 0.41 | R10: 0.21 | S10: 0.07 | T10: 0.05 | U10: 0.22 | V10: 0.32 | W10: 0.25 | X10: 0.03 | Y10: 0.55 | Z10: 0.04 | AA10: 0.49 | AB10: 0.49 | AC10: 0.39 | AD10: 0.43 | AE10: 0.21
A11: =IF(timeseries!A11<>"",timeseries!A11,"") -> 44671.375 | B11: 0.25 | C11: 0.31 | D11: 0.27 | E11: 0.13 | F11: 0.11 | G11: 0.32 | H11: 0.31 | I11: 0.36 | J11: 0.26 | K11: 0.3 | L11: 0.11 | M11: 0.35 | N11: 0.36 | O11: 0 | P11: 0.48 | Q11: 0.54 | R11: 0.38 | S11: 0.09 | T11: 0.35 | U11: 0.14 | V11: 0.39 | W11: 0.35 | X11: 0.38 | Y11: 0.55 | Z11: 0.5 | AA11: 0.48 | AB11: 0.05 | AC11: 0.21 | AD11: 0.15 | AE11: 0.01
A12: =IF(timeseries!A12<>"",timeseries!A12,"") -> 44671.417 | B12: 0.43 | C12: 0.42 | D12: 0.43 | E12: 0.32 | F12: 0.29 | G12: 0.31 | H12: 0.08 | I12: 0.23 | J12: 0.15 | K12: 0.4 | L12: 0.53 | M12: 0.04 | N12: 0.39 | O12: 0.42 | P12: 0.41 | Q12: 0.49 | R12: 0.36 | S12: 0.37 | T12: 0.44 | U12: 0.22 | V12: 0.55 | W12: 0.43 | X12: 0.36 | Y12: 0.52 | Z12: 0.38 | AA12: 0.22 | AB12: 0.25 | AC12: 0.13 | AD12: 0.49 | AE12: 0.45
A13: =IF(timeseries!A13<>"",timeseries!A13,"") -> 44671.458 | B13: 0.16 | C13: 0.11 | D13: 0.16 | E13: 0.01 | F13: 0.54 | G13: 0.28 | H13: 0.21 | I13: 0.28 | J13: 0.44 | K13: 0.39 | L13: 0.5 | M13: 0.32 | N13: 0.53 | O13: 0.04 | P13: 0.01 | Q13: 0.03 | R13: 0.09 | S13: 0.38 | T13: 0.05 | U13: 0.53 | V13: 0.04 | W13: 0.07 | X13: 0.06 | Y13: 0.05 | Z13: 0.16 | AA13: 0.46 | AB13: 0.35 | AC13: 0.47 | AD13: 0.25 | AE13: 0.12
... A481: =IF(timeseries!A481<>"",timeseries!A481,"") -> 44690.958 | B481: 0.17 | C481: 0.17 | D481: 0.11 | E481: 0.26 | F481: 0.01 | G481: 0.37 | H481: 0.02 | I481: 0.17 | J481: 0.3 | K481: 0.29 | L481: 0.3 | M481: 0.19 | N481: 0.17 | O481: 0.19 | P481: 0.51 | Q481: 0.51 | R481: 0.1 | S481: 0.02 | T481: 0.15 | U481: 0.1 | V481: 0.42 | W481: 0.02 | X481: 0.23 | Y481: 0.21 | Z481: 0.02 | AA481: 0.03 | AB481: 0.49 | AC481: 0.15 | AD481: 0.53 | AE481: 0.3

Sheet market_prices
A1: t | B1: npe,s1 | C1: npe,s2 | D1: npe,s3 | E1: npe,s4 | F1: npe,s5 | G1: npe,s6 | H1: npe,s7 | I1: npe,s8 | J1: npe,s9 | K1: npe,s10 | L1: npe,s11 | M1: npe,s12 | N1: npe,s13 | O1: npe,s14 | P1: npe,s15 | Q1: npe,s16 | R1: npe,s17 | S1: npe,s18 | T1: npe,s19 | U1: npe,s20 | V1: npe,s21 | W1: npe,s22 | X1: npe,s23 | Y1: npe,s24 | Z1: npe,s25 | AA1: npe,s26 | AB1: npe,s27 | AC1: npe,s28 | AD1: npe,s29 | AE1: npe,s30 | AF1: fcr_up,s1 | AG1: fcr_up,s2 | AH1: fcr_up,s3 | AI1: fcr_up,s4 | AJ1: fcr_up,s5 | AK1: fcr_up,s6 | AL1: fcr_up,s7 | AM1: fcr_up,s8 | AN1: fcr_up,s9 | AO1: fcr_up,s10 | AP1: fcr_up,s11 | AQ1: fcr_up,s12 | AR1: fcr_up,s13 | AS1: fcr_up,s14 | AT1: fcr_up,s15 | AU1: fcr_up,s16 | AV1: fcr_up,s17 | AW1: fcr_up,s18 | AX1: fcr_up,s19 | AY1: fcr_up,s20 | AZ1: fcr_up,s21 | BA1: fcr_up,s22 | BB1: fcr_up,s23 | BC1: fcr_up,s24 | BD1: fcr_up,s25 | BE1: fcr_up,s26 | BF1: fcr_up,s27 | BG1: fcr_up,s28 | BH1: fcr_up,s29 | BI1: fcr_up,s30
A2: 44671 | B2: 48 | C2: 48 | D2: 48 | E2: 48 | F2: 48 | G2: 48 | H2: 48 | I2: 48 | J2: 48 | K2: 48 | L2: 48 | M2: 48 | N2: 48 | O2: 48 | P2: 48 | Q2: 48 | R2: 48 | S2: 48 | T2: 48 | U2: 48 | V2: 48 | W2: 48 | X2: 48 | Y2: 48 | Z2: 48 | AA2: 48 | AB2: 48 | AC2: 48 | AD2: 48 | AE2: 48 | AF2: 4 | AG2: 4 | AH2: 4 | AI2: 4 | AJ2: 4 | AK2: 4 | AL2: 4 | AM2: 4 | AN2: 4 | AO2: 4 | AP2: 4 | AQ2: 4 | AR2: 4 | AS2: 4 | AT2: 4 | AU2: 4 | AV2: 4 | AW2: 4 | AX2: 4 | AY2: 4 | AZ2: 4 | BA2: 4 | BB2: 4 | BC2: 4 | BD2: 4 | BE2: 4 | BF2: 4 | BG2: 4 | BH2: 4 | BI2: 4
A3: 44671.042 | B3: 60 | C3: 60 | D3: 60 | E3: 60 | F3: 60 | G3: 60 | H3: 60 | I3: 60 | J3: 60 | K3: 60 | L3: 60 | M3: 60 | N3: 60 | O3: 60 | P3: 60 | Q3: 60 | R3: 60 | S3: 60 | T3: 60 | U3: 60 | V3: 60 | W3: 60 | X3: 60 | Y3: 60 | Z3: 60 | AA3: 60 | AB3: 60 | AC3: 60 | AD3: 60 | AE3: 60 | AF3: 56 | AG3: 56 | AH3: 56 | AI3: 56 | AJ3: 56 | AK3: 56 | AL3: 56 | AM3: 56 | AN3: 56 | AO3: 56 | AP3: 56 | AQ3: 56 | AR3: 56 | AS3: 56 | AT3: 56 | AU3: 56 | AV3: 56 | AW3: 56 | AX3: 56 | AY3: 56 | AZ3: 56 | BA3: 56 | BB3: 56 | BC3: 56 | BD3: 56 | BE3: 56 | BF3: 56 | BG3: 56 | BH3: 56 | BI3: 56
A4: 44671.083 | B4: 58 | C4: 87 | D4: 89 | E4: 66 | F4: 67 | G4: 69 | H4: 70 | I4: 54 | J4: 50 | K4: 53 | L4: 69 | M4: 58 | N4: 62 | O4: 69 | P4: 60 | Q4: 54 | R4: 57 | S4: 54 | T4: 59 | U4: 63 | V4: 56 | W4: 66 | X4: 61 | Y4: 54 | Z4: 66 | AA4: 58 | AB4: 50 | AC4: 65 | AD4: 54 | AE4: 53 | AF4: 44 | AG4: 52.8 | AH4: 55 | AI4: 32 | AJ4: 45 | AK4: 33 | AL4: 12 | AM4: 9 | AN4: 21 | AO4: 17 | AP4: 35 | AQ4: 46 | AR4: 27 | AS4: 46 | AT4: 35 | AU4: 25 | AV4: 10 | AW4: 1 | AX4: 41 | AY4: 18 | AZ4: 16 | BA4: 13 | BB4: 36 | BC4: 14 | BD4: 10 | BE4: 13 | BF4: 43 | BG4: 30 | BH4: 3 | BI4: 28
A5: 44671.125 | B5: 52 | C5: 64 | D5: 75 | E5: 58 | F5: 75 | G5: 75 | H5: 68 | I5: 44 | J5: 57 | K5: 54 | L5: 59 | M5: 48 | N5: 55 | O5: 62 | P5: 70 | Q5: 58 | R5: 63 | S5: 56 | T5: 53 | U5: 53 | V5: 51 | W5: 74 | X5: 64 | Y5: 51 | Z5: 57 | AA5: 68 | AB5: 46 | AC5: 55 | AD5: 63 | AE5: 58 | AF5: 36 | AG5: 57 | AH5: 46 | AI5: 32 | AJ5: 25 | AK5: 41 | AL5: 20 | AM5: 7 | AN5: 10 | AO5: 26 | AP5: 33 | AQ5: 30 | AR5: 15 | AS5: 28 | AT5: 8 | AU5: 7 | AV5: 27 | AW5: 40 | AX5: 13 | AY5: 15 | AZ5: 5 | BA5: 25 | BB5: 31 | BC5: 43 | BD5: 38 | BE5: 0 | BF5: 14 | BG5: 21 | BH5: 34 | BI5: 39
A6: 44671.167 | B6: 53 | C6: 67 | D6: 77 | E6: 52 | F6: 82 | G6: 84 | H6: 78 | I6: 42 | J6: 51 | K6: 45 | L6: 52 | M6: 46 | N6: 56 | O6: 70 | P6: 62 | Q6: 67 | R6: 59 | S6: 48 | T6: 50 | U6: 51 | V6: 51 | W6: 74 | X6: 67 | Y6: 57 | Z6: 52 | AA6: 69 | AB6: 40 | AC6: 60 | AD6: 61 | AE6: 48 | AF6: 28 | AG6: 54 | AH6: 47 | AI6: 14 | AJ6: 41 | AK6: 41 | AL6: 14 | AM6: 10 | AN6: 2 | AO6: 0 | AP6: 10 | AQ6: 7 | AR6: 1 | AS6: 31 | AT6: 29 | AU6: 2 | AV6: 15 | AW6: 30 | AX6: 11 | AY6: 4 | AZ6: 36 | BA6: 8 | BB6: 0 | BC6: 14 | BD6: 9 | BE6: 9 | BF6: 16 | BG6: 15 | BH6: 29 | BI6: 41
A7: 44671.208 | B7: 53 | C7: 65 | D7: 72 | E7: 52 | F7: 80 | G7: 92 | H7: 71 | I7: 38 | J7: 48 | K7: 38 | L7: 56 | M7: 40 | N7: 46 | O7: 73 | P7: 72 | Q7: 76 | R7: 52 | S7: 54 | T7: 55 | U7: 53 | V7: 58 | W7: 71 | X7: 77 | Y7: 54 | Z7: 52 | AA7: 63 | AB7: 38 | AC7: 63 | AD7: 64 | AE7: 38 | AF7: 33 | AG7: 53 | AH7: 37 | AI7: 24 | AJ7: 17 | AK7: 1 | AL7: 4 | AM7: 6 | AN7: 7 | AO7: 5 | AP7: 28 | AQ7: 21 | AR7: 26 | AS7: 9 | AT7: 20 | AU7: 17 | AV7: 27 | AW7: 36 | AX7: 3 | AY7: 5 | AZ7: 5 | BA7: 5 | BB7: 17 | BC7: 39 | BD7: 5 | BE7: 28 | BF7: 22 | BG7: 12 | BH7: 27 | BI7: 30
A8: 44671.25 | B8: 55 | C8: 64 | D8: 73 | E8: 52 | F8: 81 | G8: 89 | H8: 81 | I8: 28 | J8: 53 | K8: 35 | L8: 46 | M8: 40 | N8: 46 | O8: 74 | P8: 66 | Q8: 74 | R8: 49 | S8: 59 | T8: 61 | U8: 50 | V8: 50 | W8: 61 | X8: 86 | Y8: 58 | Z8: 43 | AA8: 54 | AB8: 38 | AC8: 65 | AD8: 69 | AE8: 29 | AF8: 25 | AG8: 61 | AH8: 35 | AI8: 14 | AJ8: 18 | AK8: 10 | AL8: 13 | AM8: 9 | AN8: 23 | AO8: 29 | AP8: 19 | AQ8: 33 | AR8: 12 | AS8: 13 | AT8: 32 | AU8: 30 | AV8: 33 | AW8: 10 | AX8: 46 | AY8: 30 | AZ8: 46 | BA8: 29 | BB8: 40 | BC8: 0 | BD8: 37 | BE8: 30 | BF8: 9 | BG8: 35 | BH8: 25 | BI8: 34
A9: 44671.292 | B9: 56 | C9: 63 | D9: 77 | E9: 50 | F9: 86 | G9: 79 | H9: 77 | I9: 28 | J9: 60 | K9: 44 | L9: 44 | M9: 32 | N9: 52 | O9: 73 | P9: 59 | Q9: 84 | R9: 48 | S9: 56 | T9: 53 | U9: 48 | V9: 51 | W9: 71 | X9: 80 | Y9: 68 | Z9: 50 | AA9: 45 | AB9: 40 | AC9: 57 | AD9: 65 | AE9: 21 | AF9: 29 | AG9: 64 | AH9: 25 | AI9: 3 | AJ9: 19 | AK9: 12 | AL9: 22 | AM9: 36 | AN9: 27 | AO9: 45 | AP9: 41 | AQ9: 34 | AR9: 21 | AS9: 31 | AT9: 0 | AU9: 4 | AV9: 15 | AW9: 38 | AX9: 42 | AY9: 14 | AZ9: 34 | BA9: 20 | BB9: 1 | BC9: 39 | BD9: 16 | BE9: 8 | BF9: 21 | BG9: 46 | BH9: 35 | BI9: 34
A10: 44671.333 | B10: 55 | C10: 62 | D10: 73 | E10: 51 | F10: 85 | G10: 79 | H10: 75 | I10: 32 | J10: 50 | K10: 51 | L10: 54 | M10: 29 | N10: 50 | O10: 63 | P10: 58 | Q10: 94 | R10: 44 | S10: 62 | T10: 55 | U10: 56 | V10: 58 | W10: 70 | X10: 76 | Y10: 64 | Z10: 53 | AA10: 40 | AB10: 34 | AC10: 58 | AD10: 58 | AE10: 25 | AF10: 37 | AG10: 60 | AH10: 26 | AI10: 12 | AJ10: 37 | AK10: 21 | AL10: 40 | AM10: 36 | AN10: 44 | AO10: 6 | AP10: 23 | AQ10: 21 | AR10: 2 | AS10: 41 | AT10: 46 | AU10: 30 | AV10: 26 | AW10: 25 | AX10: 43 | AY10: 9 | AZ10: 18 | BA10: 42 | BB10: 35 | BC10: 30 | BD10: 18 | BE10: 9 | BF10: 11 | BG10: 30 | BH10: 0 | BI10: 12
A11: 44671.375 | B11: 52 | C11: 62 | D11: 74 | E11: 44 | F11: 88 | G11: 79 | H11: 82 | I11: 25 | J11: 43 | K11: 52 | L11: 54 | M11: 32 | N11: 43 | O11: 71 | P11: 66 | Q11: 97 | R11: 42 | S11: 65 | T11: 63 | U11: 61 | V11: 63 | W11: 61 | X11: 67 | Y11: 55 | Z11: 49 | AA11: 44 | AB11: 42 | AC11: 56 | AD11: 61 | AE11: 25 | AF11: 28 | AG11: 65 | AH11: 26 | AI11: 20 | AJ11: 31 | AK11: 33 | AL11: 14 | AM11: 13 | AN11: 16 | AO11: 46 | AP11: 34 | AQ11: 46 | AR11: 11 | AS11: 36 | AT11: 1 | AU11: 21 | AV11: 27 | AW11: 6 | AX11: 0 | AY11: 6 | AZ11: 32 | BA11: 16 | BB11: 3 | BC11: 43 | BD11: 1 | BE11: 21 | BF11: 22 | BG11: 8 | BH11: 12 | BI11: 15
A12: 44671.417 | B12: 56 | C12: 65 | D12: 74 | E12: 34 | F12: 88 | G12: 89 | H12: 72 | I12: 19 | J12: 42 | K12: 57 | L12: 46 | M12: 28 | N12: 33 | O12: 74 | P12: 57 | Q12: 105 | R12: 42 | S12: 64 | T12: 63 | U12: 55 | V12: 70 | W12: 70 | X12: 69 | Y12: 53 | Z12: 43 | AA12: 35 | AB12: 52 | AC12: 48 | AD12: 69 | AE12: 23 | AF12: 38 | AG12: 58 | AH12: 36 | AI12: 18 | AJ12: 4 | AK12: 40 | AL12: 26 | AM12: 1 | AN12: 19 | AO12: 20 | AP12: 40 | AQ12: 15 | AR12: 38 | AS12: 31 | AT12: 10 | AU12: 21 | AV12: 42 | AW12: 20 | AX12: 41 | AY12: 21 | AZ12: 15 | BA12: 19 | BB12: 24 | BC12: 24 | BD12: 24 | BE12: 8 | BF12: 40 | BG12: 35 | BH12: 31 | BI12: 37
A13: 44671.458 | B13: 55 | C13: 63 | D13: 77 | E13: 30 | F13: 98 | G13: 91 | H13: 75 | I13: 15 | J13: 52 | K13: 59 | L13: 48 | M13: 22 | N13: 25 | O13: 82 | P13: 49 | Q13: 104 | R13: 51 | S13: 62 | T13: 69 | U13: 49 | V13: 68 | W13: 62 | X13: 75 | Y13: 56 | Z13: 35 | AA13: 36 | AB13: 42 | AC13: 49 | AD13: 77 | AE13: 21 | AF13: 30 | AG13: 54 | AH13: 36 | AI13: 3 | AJ13: 35 | AK13: 5 | AL13: 1 | AM13: 32 | AN13: 1 | AO13: 24 | AP13: 7 | AQ13: 29 | AR13: 29 | AS13: 10 | AT13: 33 | AU13: 30 | AV13: 16 | AW13: 5 | AX13: 33 | AY13: 33 | AZ13: 43 | BA13: 35 | BB13: 9 | BC13: 17 | BD13: 7 | BE13: 34 | BF13: 23 | BG13: 22 | BH13: 22 | BI13: 6
... A481: 44690.958 | B481: 54 | C481: 65 | D481: 76 | E481: -2 | F481: 11 | G481: 119 | H481: -2 | I481: 81 | J481: 122 | K481: 127 | L481: 53 | M481: 114 | N481: 30 | O481: 130 | P481: 3 | Q481: 55 | R481: 27 | S481: 121 | T481: 89 | U481: 90 | V481: 120 | W481: 95 | X481: 89 | Y481: 70 | Z481: 115 | AA481: 120 | AB481: 54 | AC481: 29 | AD481: 111 | AE481: 130 | AF481: 132 | AG481: 22 | AH481: 24 | AI481: 1 | AJ481: 5 | AK481: 5 | AL481: 4 | AM481: 16 | AN481: 34 | AO481: 5 | AP481: 12 | AQ481: 19 | AR481: 46 | AS481: 26 | AT481: 33 | AU481: 10 | AV481: 4 | AW481: 40 | AX481: 14 | AY481: 39 | AZ481: 32 | BA481: 34 | BB481: 35 | BC481: 34 | BD481: 26 | BE481: 0 | BF481: 3 | BG481: 30 | BH481: 35 | BI481: 3

Sheet balance_prices
A1: t | B1: npe,up,s1 | C1: npe,up,s2 | D1: npe,up,s3 | E1: npe,up,s4 | F1: npe,up,s5 | G1: npe,up,s6 | H1: npe,up,s7 | I1: npe,up,s8 | J1: npe,up,s9 | K1: npe,up,s10 | L1: npe,up,s11 | M1: npe,up,s12 | N1: npe,up,s13 | O1: npe,up,s14 | P1: npe,up,s15 | Q1: npe,up,s16 | R1: npe,up,s17 | S1: npe,up,s18 | T1: npe,up,s19 | U1: npe,up,s20 | V1: npe,up,s21 | W1: npe,up,s22 | X1: npe,up,s23 | Y1: npe,up,s24 | Z1: npe,up,s25 | AA1: npe,up,s26 | AB1: npe,up,s27 | AC1: npe,up,s28 | AD1: npe,up,s29 | AE1: npe,up,s30 | AF1: npe,dw,s1 | AG1: npe,dw,s2 | AH1: npe,dw,s3 | AI1: npe,dw,s4 | AJ1: npe,dw,s5 | AK1: npe,dw,s6 | AL1: npe,dw,s7 | AM1: npe,dw,s8 | AN1: npe,dw,s9 | AO1: npe,dw,s10 | AP1: npe,dw,s11 | AQ1: npe,dw,s12 | AR1: npe,dw,s13 | AS1: npe,dw,s14 | AT1: npe,dw,s15 | AU1: npe,dw,s16 | AV1: npe,dw,s17 | AW1: npe,dw,s18 | AX1: npe,dw,s19 | AY1: npe,dw,s20 | AZ1: npe,dw,s21 | BA1: npe,dw,s22 | BB1: npe,dw,s23 | BC1: npe,dw,s24 | BD1: npe,dw,s25 | BE1: npe,dw,s26 | BF1: npe,dw,s27 | BG1: npe,dw,s28 | BH1: npe,dw,s29 | BI1: npe,dw,s30
A2: =IF(timeseries!A2<>"",timeseries!A2,"") -> 44671 | B2: =0.01+market_prices!B2 -> 48.01 | C2: =0.01+market_prices!C2 -> 48.01 | D2: =0.01+market_prices!D2 -> 48.01 | E2: =0.01+market_prices!E2 -> 48.01 | F2: =0.01+market_prices!F2 -> 48.01 | G2: =0.01+market_prices!G2 -> 48.01 | H2: =0.01+market_prices!H2 -> 48.01 | I2: =0.01+market_prices!I2 -> 48.01 | ... AE2: =0.01+market_prices!AE2 -> 48.01 | AF2: =-0.01+market_prices!B2 -> 47.99 | AG2: =-0.01+market_prices!C2 -> 47.99 | AH2: =-0.01+market_prices!D2 -> 47.99 | AI2: =-0.01+market_prices!E2 -> 47.99 | AJ2: =-0.01+market_prices!F2 -> 47.99 | AK2: =-0.01+market_prices!G2 -> 47.99 | AL2: =-0.01+market_prices!H2 -> 47.99 | AM2: =-0.01+market_prices!I2 -> 47.99 | ... BI2: =-0.01+market_prices!AE2 -> 47.99
A3: =IF(timeseries!A3<>"",timeseries!A3,"") -> 44671.042 | B3: =0.01+market_prices!B3 -> 60.01 | C3: =0.01+market_prices!C3 -> 60.01 | D3: =0.01+market_prices!D3 -> 60.01 | E3: =0.01+market_prices!E3 -> 60.01 | F3: =0.01+market_prices!F3 -> 60.01 | G3: =0.01+market_prices!G3 -> 60.01 | H3: =0.01+market_prices!H3 -> 60.01 | I3: =0.01+market_prices!I3 -> 60.01 | ... AE3: =0.01+market_prices!AE3 -> 60.01 | AF3: =-0.01+market_prices!B3 -> 59.99 | AG3: =-0.01+market_prices!C3 -> 59.99 | AH3: =-0.01+market_prices!D3 -> 59.99 | AI3: =-0.01+market_prices!E3 -> 59.99 | AJ3: =-0.01+market_prices!F3 -> 59.99 | AK3: =-0.01+market_prices!G3 -> 59.99 | AL3: =-0.01+market_prices!H3 -> 59.99 | AM3: =-0.01+market_prices!I3 -> 59.99 | ... BI3: =-0.01+market_prices!AE3 -> 59.99
A4: =IF(timeseries!A4<>"",timeseries!A4,"") -> 44671.083 | B4: =0.01+market_prices!B4 -> 58.01 | C4: =0.01+market_prices!C4 -> 87.01 | D4: =0.01+market_prices!D4 -> 89.01 | E4: =0.01+market_prices!E4 -> 66.01 | F4: =0.01+market_prices!F4 -> 67.01 | G4: =0.01+market_prices!G4 -> 69.01 | H4: =0.01+market_prices!H4 -> 70.01 | I4: =0.01+market_prices!I4 -> 54.01 | ... AE4: =0.01+market_prices!AE4 -> 53.01 | AF4: =-0.01+market_prices!B4 -> 57.99 | AG4: =-0.01+market_prices!C4 -> 86.99 | AH4: =-0.01+market_prices!D4 -> 88.99 | AI4: =-0.01+market_prices!E4 -> 65.99 | AJ4: =-0.01+market_prices!F4 -> 66.99 | AK4: =-0.01+market_prices!G4 -> 68.99 | AL4: =-0.01+market_prices!H4 -> 69.99 | AM4: =-0.01+market_prices!I4 -> 53.99 | ... BI4: =-0.01+market_prices!AE4 -> 52.99
A5: =IF(timeseries!A5<>"",timeseries!A5,"") -> 44671.125 | B5: =0.01+market_prices!B5 -> 52.01 | C5: =0.01+market_prices!C5 -> 64.01 | D5: =0.01+market_prices!D5 -> 75.01 | E5: =0.01+market_prices!E5 -> 58.01 | F5: =0.01+market_prices!F5 -> 75.01 | G5: =0.01+market_prices!G5 -> 75.01 | H5: =0.01+market_prices!H5 -> 68.01 | I5: =0.01+market_prices!I5 -> 44.01 | ... AE5: =0.01+market_prices!AE5 -> 58.01 | AF5: =-0.01+market_prices!B5 -> 51.99 | AG5: =-0.01+market_prices!C5 -> 63.99 | AH5: =-0.01+market_prices!D5 -> 74.99 | AI5: =-0.01+market_prices!E5 -> 57.99 | AJ5: =-0.01+market_prices!F5 -> 74.99 | AK5: =-0.01+market_prices!G5 -> 74.99 | AL5: =-0.01+market_prices!H5 -> 67.99 | AM5: =-0.01+market_prices!I5 -> 43.99 | ... BI5: =-0.01+market_prices!AE5 -> 57.99
A6: =IF(timeseries!A6<>"",timeseries!A6,"") -> 44671.167 | B6: =0.01+market_prices!B6 -> 53.01 | C6: =0.01+market_prices!C6 -> 67.01 | D6: =0.01+market_prices!D6 -> 77.01 | E6: =0.01+market_prices!E6 -> 52.01 | F6: =0.01+market_prices!F6 -> 82.01 | G6: =0.01+market_prices!G6 -> 84.01 | H6: =0.01+market_prices!H6 -> 78.01 | I6: =0.01+market_prices!I6 -> 42.01 | ... AE6: =0.01+market_prices!AE6 -> 48.01 | AF6: =-0.01+market_prices!B6 -> 52.99 | AG6: =-0.01+market_prices!C6 -> 66.99 | AH6: =-0.01+market_prices!D6 -> 76.99 | AI6: =-0.01+market_prices!E6 -> 51.99 | AJ6: =-0.01+market_prices!F6 -> 81.99 | AK6: =-0.01+market_prices!G6 -> 83.99 | AL6: =-0.01+market_prices!H6 -> 77.99 | AM6: =-0.01+market_prices!I6 -> 41.99 | ... BI6: =-0.01+market_prices!AE6 -> 47.99
A7: =IF(timeseries!A7<>"",timeseries!A7,"") -> 44671.208 | B7: =0.01+market_prices!B7 -> 53.01 | C7: =0.01+market_prices!C7 -> 65.01 | D7: =0.01+market_prices!D7 -> 72.01 | E7: =0.01+market_prices!E7 -> 52.01 | F7: =0.01+market_prices!F7 -> 80.01 | G7: =0.01+market_prices!G7 -> 92.01 | H7: =0.01+market_prices!H7 -> 71.01 | I7: =0.01+market_prices!I7 -> 38.01 | ... AE7: =0.01+market_prices!AE7 -> 38.01 | AF7: =-0.01+market_prices!B7 -> 52.99 | AG7: =-0.01+market_prices!C7 -> 64.99 | AH7: =-0.01+market_prices!D7 -> 71.99 | AI7: =-0.01+market_prices!E7 -> 51.99 | AJ7: =-0.01+market_prices!F7 -> 79.99 | AK7: =-0.01+market_prices!G7 -> 91.99 | AL7: =-0.01+market_prices!H7 -> 70.99 | AM7: =-0.01+market_prices!I7 -> 37.99 | ... BI7: =-0.01+market_prices!AE7 -> 37.99
A8: =IF(timeseries!A8<>"",timeseries!A8,"") -> 44671.25 | B8: =0.01+market_prices!B8 -> 55.01 | C8: =0.01+market_prices!C8 -> 64.01 | D8: =0.01+market_prices!D8 -> 73.01 | E8: =0.01+market_prices!E8 -> 52.01 | F8: =0.01+market_prices!F8 -> 81.01 | G8: =0.01+market_prices!G8 -> 89.01 | H8: =0.01+market_prices!H8 -> 81.01 | I8: =0.01+market_prices!I8 -> 28.01 | ... AE8: =0.01+market_prices!AE8 -> 29.01 | AF8: =-0.01+market_prices!B8 -> 54.99 | AG8: =-0.01+market_prices!C8 -> 63.99 | AH8: =-0.01+market_prices!D8 -> 72.99 | AI8: =-0.01+market_prices!E8 -> 51.99 | AJ8: =-0.01+market_prices!F8 -> 80.99 | AK8: =-0.01+market_prices!G8 -> 88.99 | AL8: =-0.01+market_prices!H8 -> 80.99 | AM8: =-0.01+market_prices!I8 -> 27.99 | ... BI8: =-0.01+market_prices!AE8 -> 28.99
A9: =IF(timeseries!A9<>"",timeseries!A9,"") -> 44671.292 | B9: =0.01+market_prices!B9 -> 56.01 | C9: =0.01+market_prices!C9 -> 63.01 | D9: =0.01+market_prices!D9 -> 77.01 | E9: =0.01+market_prices!E9 -> 50.01 | F9: =0.01+market_prices!F9 -> 86.01 | G9: =0.01+market_prices!G9 -> 79.01 | H9: =0.01+market_prices!H9 -> 77.01 | I9: =0.01+market_prices!I9 -> 28.01 | ... AE9: =0.01+market_prices!AE9 -> 21.01 | AF9: =-0.01+market_prices!B9 -> 55.99 | AG9: =-0.01+market_prices!C9 -> 62.99 | AH9: =-0.01+market_prices!D9 -> 76.99 | AI9: =-0.01+market_prices!E9 -> 49.99 | AJ9: =-0.01+market_prices!F9 -> 85.99 | AK9: =-0.01+market_prices!G9 -> 78.99 | AL9: =-0.01+market_prices!H9 -> 76.99 | AM9: =-0.01+market_prices!I9 -> 27.99 | ... BI9: =-0.01+market_prices!AE9 -> 20.99
A10: =IF(timeseries!A10<>"",timeseries!A10,"") -> 44671.333 | B10: =0.01+market_prices!B10 -> 55.01 | C10: =0.01+market_prices!C10 -> 62.01 | D10: =0.01+market_prices!D10 -> 73.01 | E10: =0.01+market_prices!E10 -> 51.01 | F10: =0.01+market_prices!F10 -> 85.01 | G10: =0.01+market_prices!G10 -> 79.01 | H10: =0.01+market_prices!H10 -> 75.01 | I10: =0.01+market_prices!I10 -> 32.01 | ... AE10: =0.01+market_prices!AE10 -> 25.01 | AF10: =-0.01+market_prices!B10 -> 54.99 | AG10: =-0.01+market_prices!C10 -> 61.99 | AH10: =-0.01+market_prices!D10 -> 72.99 | AI10: =-0.01+market_prices!E10 -> 50.99 | AJ10: =-0.01+market_prices!F10 -> 84.99 | AK10: =-0.01+market_prices!G10 -> 78.99 | AL10: =-0.01+market_prices!H10 -> 74.99 | AM10: =-0.01+market_prices!I10 -> 31.99 | ... BI10: =-0.01+market_prices!AE10 -> 24.99
